Workbook

Sheet Arvind
A1: Simulations | B1: count | C1: 5000
A2: Period 2024 | B2: Days | C2: 365
A3: Non Stochastic Drivers
A4: Refining Throughput Volume | B4: k BPD | C4: 2922
A5: Ref. Operating Expenses (excl. D&A) | B5: $ Millions | C5: 1307
A6: Ref. D&A Expense | B6: $ Millions | C6: 707
A7: Renewable Diesel Sales Volume | B7: k BPD | C7: 2732
A8: RD Operating Expenses (excl. D&A) | B8: $ Millions | C8: 72 | I8: Driver | J8: ULS Spread | K8: CBOB Spread | L8: RD Feed (UCO) | M8: RD RIN | N8: Eth. Feed (Corn) | O8: Eth. Price (Ethanol)
A9: RD D&A Expense | B9: $ Millions | C9: 61 | I9: 1. Ref. Spread ULS | J9: 1 | K9: 0.9 | L9: 0.15 | M9: 0.1 | N9: -0.1 | O9: 0.05
A10: Ethanol Production Volume | B10: k BPD | C10: 4583 | I10: 2. Ref. Spread CBOB | J10: 0.9 | K10: 1 | L10: 0.1 | M10: 0.05 | N10: -0.05 | O10: 0.1
A11: Eth. Operating Expenses (excl. D&A | B11: $ Millions | C11: 144 | I11: 3. RD Feed (UCO) | J11: 0.15 | K11: 0.1 | L11: 1 | M11: 0.5 | N11: 0.35 | O11: 0.25
A12: Eth. D&A Expense | C12: 19 | I12: 4. RD RIN | J12: 0.1 | K12: 0.05 | L12: 0.5 | M12: 1 | N12: 0.3 | O12: 0.4
A13: Stochastic Drivers | C13: Mean | D13: ST. Dev | I13: 5. Eth. Feed (Corn) | J13: -0.1 | K13: -0.05 | L13: 0.35 | M13: 0.3 | N13: 1 | O13: 0.8
A14: Ref. Spread ULS Diesel less WTI | B14: $/bbl | C14: 20.6 | D14: 4.12 | I14: 6. Eth. Price (Ethanol) | J14: 0.05 | K14: 0.1 | L14: 0.25 | M14: 0.4 | N14: 0.8 | O14: 1
A15: Ref. Spread CBOB Gas less WTI | B15: $/bbl | C15: 14.91 | D15: 2.98
A16: RD Feedstock Cost (USGC UCO) | B16: $/lb | C16: 0.56 | D16: 0.11 | T16: SUMMARY OUTPUT
A17: RD Reg. Price (Biodiesel RIN) | B17: $/RIN | C17: 1.09 | D17: 0.22
A18: Eth. Feedstock Cost (CBOT Corn) | B18: $/bushel | C18: 4.52 | D18: 0.9 | T18: Regression Statistics
A19: Eth. Product Price (NY Harbor Ethanol) | B19: $/gallon | C19: 1.84 | D19: 0.37 | T19: Multiple R | U19: 1
A20: Results For Adjusted Operating Income | T20: R Square | U20: 1
A21: Average | B21: $ Millions | D21: =AVERAGE(R28:R5027) -> 66845427 | T21: Adjusted R Square | U21: 1
A22: Standard Deviation | B22: $ Millions | D22: =STDEV(R28:R5027) -> 13895465 | T22: Standard Error | U22: 6.91271e-09
A23: Median | B23: $ Millions | D23: =MEDIAN(R28:R5027) -> 66822397 | T23: Observations | U23: 5000
A24: Worst 5% (Var 95%) | B24: $ Millions | D24: =_xlfn.PERCENTILE.EXC(R28:R5027,0.05) -> 44080809
A25: Best 5% | B25: $ Millions | D25: =_xlfn.PERCENTILE.EXC(R29:R5028,0.95) -> 88826571 | T25: ANOVA
U26: df | V26: SS | W26: MS | X26: F | Y26: Significance F
C27: Z1 value | D27: Z2 value | E27: Z3 value | F27: Z4 value | G27: Z5 value | H27: Z6 value | I27: ULS Diesel less WTI | J27: Spread CBOB Gas less WTI | K27: RD Feedstock Cost (USGC UCO) | L27: RD Reg. Price (Biodiesel RIN) | M27: Eth. Feedstock Cost (CBOT Corn) | N27: Eth. Product Price (NY Harbor Ethanol) | O27: Refining Operating Income | P27: RD Operating Income | Q27: Ethanol Operating Income | R27: Total Adjusted Operating Income | T27: Regression | U27: 6 | V27: 6.82794e+16 | W27: 1.14e+16 | X27: 2.38e+32 | Y27: 0 | AD27: Y1 | AE27: Y2 | AF27: Y3 | AG27: Y4 | AH27: Y5 | AI27: Y6
C28: {=_xlfn.NORM.S.INV(_xlfn.RANDARRAY(5000))} -> -2.138727 | D28: {=_xlfn.NORM.S.INV(_xlfn.RANDARRAY(5000))} -> -1.0511294 | E28: {=_xlfn.NORM.S.INV(_xlfn.RANDARRAY(5000))} -> -1.2589502 | F28: {=_xlfn.NORM.S.INV(_xlfn.RANDARRAY(5000))} -> -2.2234653 | G28: {=_xlfn.NORM.S.INV(_xlfn.RANDARRAY(5000))} -> 1.8836262 | H28: {=_xlfn.NORM.S.INV(_xlfn.RANDARRAY(5000))} -> 0.86625034 | I28: =$C$14+AD28*$D$14 -> 5.5991518 | J28: =$C$15+AE28*$D$15 -> 5.3125875 | K28: =$C$16+AF28*$D$16 -> 1100000.4 | L28: =$C$17+AG28*$D$17 -> 0.60428806 | M28: =$C$18+AH28*$D$18 -> 6.0818451 | N28: =$C$19+AI28*$D$19 -> 2.194082 | O28: =(I28+J28)/2*$C$4*365-$C$5-$C$6 -> 5816834.6 | P28: =(L28/1.7*42+I28)*$C$7*365-$C$8-$C$9 -> 20470598 | Q28: =(N28-M28/2.8)*$C$10*365-$C$11-$C$12 -> 36629.189 | R28: =O28+P28+Q28 -> 26324062 | T28: Residual | U28: 4993 | V28: 2.38594e-13 | W28: 4.78e-17 | AD28: =SUMPRODUCT(C28:H28,$J$9:$O$9) -> -3.6409826 | AE28: =SUMPRODUCT(C28:H28,$J$10:$O$10) -> -3.2206082 | AF28: 9999999 | AG28: =SUMPRODUCT(C28:H28,$J$12:$O$12) -> -2.2077816 | AH28: =SUMPRODUCT(C28:H28,$J$13:$O$13) -> 1.7353835 | AI28: =SUMPRODUCT(C28:H28,$J$14:$O$14) -> 0.95697834
C29: 0.68932027 | D29: -1.8514305 | E29: -0.0008968515 | F29: 0.1227327 | G29: -0.74645462 | H29: 0.9213479 | I29: =$C$14+AD29*$D$14 -> 17.122244 | J29: =$C$15+AE29*$D$15 -> 11.645297 | K29: =$C$16+AF29*$D$16 -> 0.55425826 | L29: =$C$17+AG29*$D$17 -> 1.1435145 | M29: =$C$18+AH29*$D$18 -> 4.5656922 | N29: =$C$19+AI29*$D$19 -> 1.9222791 | O29: =(I29+J29)/2*$C$4*365-$C$5-$C$6 -> 15338709 | P29: =(L29/1.7*42+I29)*$C$7*365-$C$8-$C$9 -> 45245691 | Q29: =(N29-M29/2.8)*$C$10*365-$C$11-$C$12 -> 487749.11 | R29: =O29+P29+Q29 -> 61072149 | T29: Total | U29: 4999 | V29: 6.82794e+16 | AD29: =SUMPRODUCT(C29:H29,$J$9:$O$9) -> -0.84411557 | AE29: =SUMPRODUCT(C29:H29,$J$10:$O$10) -> -1.0955378 | AF29: =SUMPRODUCT(C29:H29,$J$11:$O$11) -> -0.052197654 | AG29: =SUMPRODUCT(C29:H29,$J$12:$O$12) -> 0.24324755 | AH29: =SUMPRODUCT(C29:H29,$J$13:$O$13) -> 0.050769108 | AI29: =SUMPRODUCT(C29:H29,$J$14:$O$14) -> 0.22237603
C30: 1.2938344 | D30: -0.21183807 | E30: -0.92371424 | F30: 0.55699845 | G30: -1.6485307 | H30: 0.47214063 | I30: =$C$14+AD30*$D$14 -> 25.580186 | J30: =$C$15+AE30*$D$15 -> 17.942841 | K30: =$C$16+AF30*$D$16 -> 0.45755983 | L30: =$C$17+AG30*$D$17 -> 1.0698106 | M30: =$C$18+AH30*$D$18 -> 3.1287709 | N30: =$C$19+AI30*$D$19 -> 1.5398171 | O30: =(I30+J30)/2*$C$4*365-$C$5-$C$6 -> 23207293 | P30: =(L30/1.7*42+I30)*$C$7*365-$C$8-$C$9 -> 51863997 | Q30: =(N30-M30/2.8)*$C$10*365-$C$11-$C$12 -> 706423.8 | R30: =O30+P30+Q30 -> 75777713 | AD30: =SUMPRODUCT(C30:H30,$J$9:$O$9) -> 1.2087829 | AE30: =SUMPRODUCT(C30:H30,$J$10:$O$10) -> 1.017732 | AF30: =SUMPRODUCT(C30:H30,$J$11:$O$11) -> -0.93127424 | AG30: =SUMPRODUCT(C30:H30,$J$12:$O$12) -> -0.091770086 | AH30: =SUMPRODUCT(C30:H30,$J$13:$O$13) -> -1.5458101 | AI30: =SUMPRODUCT(C30:H30,$J$14:$O$14) -> -0.81130516
C31: 0.72282977 | D31: 0.26852996 | E31: 0.89375877 | F31: -0.49698641 | G31: -0.51830656 | H31: 1.6785786 | I31: =$C$14+AD31*$D$14 -> 25.480682 | J31: =$C$15+AE31*$D$15 -> 18.418582 | K31: =$C$16+AF31*$D$16 -> 0.67206584 | L31: =$C$17+AG31*$D$17 -> 1.2113392 | M31: =$C$18+AH31*$D$18 -> 5.3323098 | N31: =$C$19+AI31*$D$19 -> 2.340082 | O31: =(I31+J31)/2*$C$4*365-$C$5-$C$6 -> 23407927 | P31: =(L31/1.7*42+I31)*$C$7*365-$C$8-$C$9 -> 55251503 | Q31: =(N31-M31/2.8)*$C$10*365-$C$11-$C$12 -> 728649.73 | R31: =O31+P31+Q31 -> 79388079 | U31: Coefficients | V31: Standard Error | W31: t Stat | X31: P-value | Y31: Lower 95% | Z31: Upper 95% | AA31: Lower 95.0% | AB31: Upper 95.0% | AD31: =SUMPRODUCT(C31:H31,$J$9:$O$9) -> 1.1846315 | AE31: =SUMPRODUCT(C31:H31,$J$10:$O$10) -> 1.1773765 | AF31: =SUMPRODUCT(C31:H31,$J$11:$O$11) -> 1.0187804 | AG31: =SUMPRODUCT(C31:H31,$J$12:$O$12) -> 0.55154192 | AH31: =SUMPRODUCT(C31:H31,$J$13:$O$13) -> 0.90256648 | AI31: =SUMPRODUCT(C31:H31,$J$14:$O$14) -> 1.351573
C32: -0.68597854 | D32: 1.2521731 | E32: 1.1923436 | F32: -0.20545646 | G32: 0.021195703 | H32: 1.4250897 | I32: =$C$14+AD32*$D$14 -> 23.353882 | J32: =$C$15+AE32*$D$15 -> 17.547905 | K32: =$C$16+AF32*$D$16 -> 0.72231895 | L32: =$C$17+AG32*$D$17 -> 1.3014466 | M32: =$C$18+AH32*$D$18 -> 5.890646 | N32: =$C$19+AI32*$D$19 -> 2.4870812 | O32: =(I32+J32)/2*$C$4*365-$C$5-$C$6 -> 21809478 | P32: =(L32/1.7*42+I32)*$C$7*365-$C$8-$C$9 -> 55350604 | Q32: =(N32-M32/2.8)*$C$10*365-$C$11-$C$12 -> 640984.21 | R32: =O32+P32+Q32 -> 77801066 | T32: Intercept | U32: -2014 | V32: 1.20949e-09 | W32: -1700000000000 | X32: 0 | Y32: -2014 | Z32: -2014 | AA32: -2014 | AB32: -2014 | AD32: =SUMPRODUCT(C32:H32,$J$9:$O$9) -> 0.66841804 | AE32: =SUMPRODUCT(C32:H32,$J$10:$O$10) -> 0.88520311 | AF32: =SUMPRODUCT(C32:H32,$J$11:$O$11) -> 1.4756268 | AG32: =SUMPRODUCT(C32:H32,$J$12:$O$12) -> 0.96112074 | AH32: =SUMPRODUCT(C32:H32,$J$13:$O$13) -> 1.52294 | AI32: =SUMPRODUCT(C32:H32,$J$14:$O$14) -> 1.748868
C33: -0.64743937 | D33: 0.40172931 | E33: -0.22684791 | F33: 0.12553865 | G33: 1.0249222 | H33: 1.8303847 | I33: =$C$14+AD33*$D$14 -> 19.288483 | J33: =$C$15+AE33*$D$15 -> 14.714567 | K33: =$C$16+AF33*$D$16 -> 0.62548271 | L33: =$C$17+AG33*$D$17 -> 1.3115593 | M33: =$C$18+AH33*$D$18 -> 6.7629371 | N33: =$C$19+AI33*$D$19 -> 2.821102 | O33: =(I33+J33)/2*$C$4*365-$C$5-$C$6 -> 18130622 | P33: =(L33/1.7*42+I33)*$C$7*365-$C$8-$C$9 -> 51545810 | Q33: =(N33-M33/2.8)*$C$10*365-$C$11-$C$12 -> 678602.51 | R33: =O33+P33+Q33 -> 70355035 | T33: X Variable 1 | U33: 533265 | V33: 2.40354e-11 | W33: 2.22e+16 | X33: 0 | Y33: 533265 | Z33: 533265 | AA33: 533265 | AB33: 533265 | AD33: =SUMPRODUCT(C33:H33,$J$9:$O$9) -> -0.3183293 | AE33: =SUMPRODUCT(C33:H33,$J$10:$O$10) -> -0.065581622 | AF33: =SUMPRODUCT(C33:H33,$J$11:$O$11) -> 0.59529739 | AG33: =SUMPRODUCT(C33:H33,$J$12:$O$12) -> 1.0070878 | AH33: =SUMPRODUCT(C33:H33,$J$13:$O$13) -> 2.4921523 | AI33: =SUMPRODUCT(C33:H33,$J$14:$O$14) -> 2.6516269
C34: -0.30091092 | D34: -0.088567651 | E34: 0.34709085 | F34: -0.42782958 | G34: 2.9338752 | H34: -1.4309075 | I34: =$C$14+AD34*$D$14 -> 17.566551 | J34: =$C$15+AE34*$D$15 -> 13.015154 | K34: =$C$16+AF34*$D$16 -> 0.64231433 | L34: =$C$17+AG34*$D$17 -> 1.0941791 | M34: =$C$18+AH34*$D$18 -> 6.1551214 | N34: =$C$19+AI34*$D$19 -> 2.1389346 | O34: =(I34+J34)/2*$C$4*365-$C$5-$C$6 -> 16306139 | P34: =(L34/1.7*42+I34)*$C$7*365-$C$8-$C$9 -> 44473308 | Q34: =(N34-M34/2.8)*$C$10*365-$C$11-$C$12 -> -99398.387 | R34: =O34+P34+Q34 -> 60680049 | T34: X Variable 2 | U34: 533265 | V34: 3.94736e-11 | W34: 1.35e+16 | X34: 0 | Y34: 533265 | Z34: 533265 | AA34: 533265 | AB34: 533265 | AD34: =SUMPRODUCT(C34:H34,$J$9:$O$9) -> -0.73627403 | AE34: =SUMPRODUCT(C34:H34,$J$10:$O$10) -> -0.63585438 | AF34: =SUMPRODUCT(C34:H34,$J$11:$O$11) -> 0.74831211 | AG34: =SUMPRODUCT(C34:H34,$J$12:$O$12) -> 0.018995939 | AH34: =SUMPRODUCT(C34:H34,$J$13:$O$13) -> 1.8168016 | AI34: =SUMPRODUCT(C34:H34,$J$14:$O$14) -> 0.80793124
C35: -0.74269291 | D35: 1.0763432 | E35: -1.3052344 | F35: -1.7376548 | G35: 0.61786484 | H35: 0.090134483 | I35: =$C$14+AD35*$D$14 -> 19.772645 | J35: =$C$15+AE35*$D$15 -> 15.412528 | K35: =$C$16+AF35*$D$16 -> 0.34670504 | L35: =$C$17+AG35*$D$17 -> 0.60835161 | M35: =$C$18+AH35*$D$18 -> 4.2790665 | N35: =$C$19+AI35*$D$19 -> 1.7044155 | O35: =(I35+J35)/2*$C$4*365-$C$5-$C$6 -> 18761007 | P35: =(L35/1.7*42+I35)*$C$7*365-$C$8-$C$9 -> 34704232 | Q35: =(N35-M35/2.8)*$C$10*365-$C$11-$C$12 -> 294545.86 | R35: =O35+P35+Q35 -> 53759785 | T35: X Variable 3 | U35: 1.73225e-10 | V35: 9.02135e-10 | W35: 0.192017 | X35: 0.847737 | Y35: -1.59535e-09 | Z35: 1.94e-09 | AA35: -1.6e-09 | AB35: 1.94e-09 | AD35: =SUMPRODUCT(C35:H35,$J$9:$O$9) -> -0.20081443 | AE35: =SUMPRODUCT(C35:H35,$J$10:$O$10) -> 0.16863361 | AF35: =SUMPRODUCT(C35:H35,$J$11:$O$11) -> -1.9390451 | AG35: =SUMPRODUCT(C35:H35,$J$12:$O$12) -> -2.1893109 | AH35: =SUMPRODUCT(C35:H35,$J$13:$O$13) -> -0.26770391 | AI35: =SUMPRODUCT(C35:H35,$J$14:$O$14) -> -0.36644448
C36: 0.72235041 | D36: 0.80700173 | E36: 1.3461984 | F36: -1.1130191 | G36: 0.73485182 | H36: -1.9023263 | I36: =$C$14+AD36*$D$14 -> 26.247195 | J36: =$C$15+AE36*$D$15 -> 18.81115 | K36: =$C$16+AF36*$D$16 -> 0.6436394 | L36: =$C$17+AG36*$D$17 -> 0.89908186 | M36: =$C$18+AH36*$D$18 -> 3.8339024 | N36: =$C$19+AI36*$D$19 -> 1.3566745 | O36: =(I36+J36)/2*$C$4*365-$C$5-$C$6 -> 24026024 | P36: =(L36/1.7*42+I36)*$C$7*365-$C$8-$C$9 -> 48323016 | Q36: =(N36-M36/2.8)*$C$10*365-$C$11-$C$12 -> -21200.713 | R36: =O36+P36+Q36 -> 72327839 | T36: X Variable 4 | U36: -4.63704e-10 | V36: 4.43929e-10 | W36: -1.04455 | X36: 0.296284 | Y36: -1.334e-09 | Z36: 4.07e-10 | AA36: -1.3e-09 | AB36: 4.07e-10 | AD36: =SUMPRODUCT(C36:H36,$J$9:$O$9) -> 1.3706783 | AE36: =SUMPRODUCT(C36:H36,$J$10:$O$10) -> 1.3091108 | AF36: =SUMPRODUCT(C36:H36,$J$11:$O$11) -> 0.76035814 | AG36: =SUMPRODUCT(C36:H36,$J$12:$O$12) -> -0.86780973 | AH36: =SUMPRODUCT(C36:H36,$J$13:$O$13) -> -0.76233063 | AI36: =SUMPRODUCT(C36:H36,$J$14:$O$14) -> -1.3062852
C37: 0.8872776 | D37: -0.46676485 | E37: 0.58832529 | F37: 0.48688083 | G37: 1.7839988 | H37: -0.39375817 | I37: =$C$14+AD37*$D$14 -> 22.272878 | J37: =$C$15+AE37*$D$15 -> 15.76343 | K37: =$C$16+AF37*$D$16 -> 0.7188555 | L37: =$C$17+AG37*$D$17 -> 1.3593085 | M37: =$C$18+AH37*$D$18 -> 6.1000228 | N37: =$C$19+AI37*$D$19 -> 2.3479959 | O37: =(I37+J37)/2*$C$4*365-$C$5-$C$6 -> 20281418 | P37: =(L37/1.7*42+I37)*$C$7*365-$C$8-$C$9 -> 55698146 | Q37: =(N37-M37/2.8)*$C$10*365-$C$11-$C$12 -> 283235.83 | R37: =O37+P37+Q37 -> 76262800 | T37: X Variable 5 | U37: -2.90703e-10 | V37: 1.10024e-10 | W37: -2.64218 | X37: 0.008263 | Y37: -5.06398e-10 | Z37: -7.5e-11 | AA37: -5.1e-10 | AB37: -7.5e-11 | AD37: =SUMPRODUCT(C37:H37,$J$9:$O$9) -> 0.40603833 | AE37: =SUMPRODUCT(C37:H37,$J$10:$O$10) -> 0.28638581 | AF37: =SUMPRODUCT(C37:H37,$J$11:$O$11) -> 1.4441409 | AG37: =SUMPRODUCT(C37:H37,$J$12:$O$12) -> 1.2241294 | AH37: =SUMPRODUCT(C37:H37,$J$13:$O$13) -> 1.7555808 | AI37: =SUMPRODUCT(C37:H37,$J$14:$O$14) -> 1.3729619
C38: -0.43700989 | D38: 0.63589552 | E38: -0.34640669 | F38: -0.5628743 | G38: -1.9273651 | H38: 0.58705271 | I38: =$C$14+AD38*$D$14 -> 21.626444 | J38: =$C$15+AE38*$D$15 -> 15.90793 | K38: =$C$16+AF38*$D$16 -> 0.43266176 | L38: =$C$17+AG38*$D$17 -> 0.8498981 | M38: =$C$18+AH38*$D$18 -> 2.9576708 | N38: =$C$19+AI38*$D$19 -> 1.3868049 | O38: =(I38+J38)/2*$C$4*365-$C$5-$C$6 -> 20013754 | P38: =(L38/1.7*42+I38)*$C$7*365-$C$8-$C$9 -> 42503593 | Q38: =(N38-M38/2.8)*$C$10*365-$C$11-$C$12 -> 552685.5 | R38: =O38+P38+Q38 -> 63070033 | T38: X Variable 6 | U38: -2.76609e-10 | V38: 2.59822e-10 | W38: -1.06461 | X38: 0.287105 | Y38: -7.85975e-10 | Z38: 2.33e-10 | AA38: -7.9e-10 | AB38: 2.33e-10 | AD38: =SUMPRODUCT(C38:H38,$J$9:$O$9) -> 0.24913678 | AE38: =SUMPRODUCT(C38:H38,$J$10:$O$10) -> 0.33487575 | AF38: =SUMPRODUCT(C38:H38,$J$11:$O$11) -> -1.1576204 | AG38: =SUMPRODUCT(C38:H38,$J$12:$O$12) -> -1.0913723 | AH38: =SUMPRODUCT(C38:H38,$J$13:$O$13) -> -1.7359213 | AI38: =SUMPRODUCT(C38:H38,$J$14:$O$14) -> -1.2248517
C39: -0.46840615 | D39: -1.3286987 | E39: 0.41726286 | F39: 0.68289202 | G39: -1.263852 | H39: -0.23619819 | I39: =$C$14+AD39*$D$14 -> 14.754622 | J39: =$C$15+AE39*$D$15 -> 10.038235 | K39: =$C$16+AF39*$D$16 -> 0.56595984 | L39: =$C$17+AG39*$D$17 -> 1.1570149 | M39: =$C$18+AH39*$D$18 -> 3.6302372 | N39: =$C$19+AI39*$D$19 -> 1.460344 | O39: =(I39+J39)/2*$C$4*365-$C$5-$C$6 -> 13219149 | P39: =(L39/1.7*42+I39)*$C$7*365-$C$8-$C$9 -> 43217344 | Q39: =(N39-M39/2.8)*$C$10*365-$C$11-$C$12 -> 273892.14 | R39: =O39+P39+Q39 -> 56710385 | AD39: =SUMPRODUCT(C39:H39,$J$9:$O$9) -> -1.4187811 | AE39: =SUMPRODUCT(C39:H39,$J$10:$O$10) -> -1.6348206 | AF39: =SUMPRODUCT(C39:H39,$J$11:$O$11) -> 0.054180335 | AG39: =SUMPRODUCT(C39:H39,$J$12:$O$12) -> 0.30461303 | AH39: =SUMPRODUCT(C39:H39,$J$13:$O$13) -> -0.98862535 | AI39: =SUMPRODUCT(C39:H39,$J$14:$O$14) -> -1.0260974
C40: 0.85608364 | D40: 1.7986533 | E40: 0.20517718 | F40: -0.39180465 | G40: 0.071897254 | H40: 0.31013575 | I40: =$C$14+AD40*$D$14 -> 30.796113 | J40: =$C$15+AE40*$D$15 -> 22.650475 | K40: =$C$16+AF40*$D$16 -> 0.60622758 | L40: =$C$17+AG40*$D$17 -> 1.0970287 | M40: =$C$18+AH40*$D$18 -> 4.6088619 | N40: =$C$19+AI40*$D$19 -> 2.0194113 | O40: =(I40+J40)/2*$C$4*365-$C$5-$C$6 -> 28499181 | P40: =(L40/1.7*42+I40)*$C$7*365-$C$8-$C$9 -> 57735766 | Q40: =(N40-M40/2.8)*$C$10*365-$C$11-$C$12 -> 624440.64 | R40: =O40+P40+Q40 -> 86859387 | T40: SUMMARY OUTPUT | AD40: =SUMPRODUCT(C40:H40,$J$9:$O$9) -> 2.4747848 | AE40: =SUMPRODUCT(C40:H40,$J$10:$O$10) -> 2.5974748 | AF40: =SUMPRODUCT(C40:H40,$J$11:$O$11) -> 0.42025071 | AG40: =SUMPRODUCT(C40:H40,$J$12:$O$12) -> 0.031948444 | AH40: =SUMPRODUCT(C40:H40,$J$13:$O$13) -> 0.098735446 | AI40: =SUMPRODUCT(C40:H40,$J$14:$O$14) -> 0.4848955
...

Sheet Arvind 2
A1: Stochastic Drivers | B1: Mean | C1: ST. Dev | E1: Driver | F1: ULS Spread | G1: CBOB Spread | H1: RD Feed (UCO) | I1: RD RIN | J1: Eth. Feed (Corn) | K1: Eth. Price (Ethanol) | R1: Driver | S1: Refining OI Beta | T1: RD OI Beta | U1: Ethanol OI Beta | V1: Base Refining OI | W1: Base RD OI | X1: Base Ethanol OI
A2: Ref. Spread ULS Diesel less WTI | B2: 20.6 | C2: 4.12 | E2: 1. Ref. Spread ULS | F2: 1 | G2: 0.9 | H2: 0.15 | I2: 0.1 | J2: -0.1 | K2: 0.05 | R2: 1. Ref. Spread ULS | S2: 0.53 | T2: 0.997 | U2: 0 | V2: 1307 | W2: 2732 | X2: 4583
A3: Ref. Spread CBOB Gas less WTI | B3: 14.91 | C3: 2.98 | E3: 2. Ref. Spread CBOB | F3: 0.9 | G3: 1 | H3: 0.1 | I3: 0.05 | J3: -0.05 | K3: 0.1 | R3: 2. Ref. Spread CBOB | S3: 0.53 | T3: 0 | U3: 0
A4: RD Feedstock Cost (USGC UCO) | B4: 0.56 | C4: 0.11 | E4: 3. RD Feed (UCO) | F4: 0.15 | G4: 0.1 | H4: 1 | I4: 0.5 | J4: 0.35 | K4: 0.25 | R4: 3. RD Feed (UCO) | S4: 0 | T4: 0 | U4: 0
A5: RD Reg. Price (Biodiesel RIN) | B5: 1.09 | C5: 0.22 | E5: 4. RD RIN | F5: 0.1 | G5: 0.05 | H5: 0.5 | I5: 1 | J5: 0.3 | K5: 0.4 | R5: 4. RD RIN | S5: 0 | T5: 24.6 | U5: 0
A6: Eth. Feedstock Cost (CBOT Corn) | B6: 4.52 | C6: 0.9 | E6: 5. Eth. Feed (Corn) | F6: -0.1 | G6: -0.05 | H6: 0.35 | I6: 0.3 | J6: 1 | K6: 0.8 | R6: 5. Eth. Feed (Corn) | S6: 0 | T6: 0 | U6: -0.597
A7: Eth. Product Price (NY Harbor Ethanol) | B7: 1.84 | C7: 0.37 | E7: 6. Eth. Price (Ethanol) | F7: 0.05 | G7: 0.1 | H7: 0.25 | I7: 0.4 | J7: 0.8 | K7: 1 | R7: 6. Eth. Price (Ethanol) | S7: 0 | T7: 0 | U7: 1.67
D14: SUMMARY OUTPUT
D16: Regression Statistics
D17: Multiple R | E17: 1
D18: R Square | E18: 1
D19: Adjusted R Square | E19: 1
D20: Standard Error | E20: 6.91271e-09
D21: Observations | E21: 5000
D23: ANOVA
E24: df | F24: SS | G24: MS | H24: F | I24: Significance F
D25: Regression | E25: 6 | F25: 6.82794e+16 | G25: 1.14e+16 | H25: 2.38e+32 | I25: 0
D26: Residual | E26: 4993 | F26: 2.38594e-13 | G26: 4.78e-17
D27: Total | E27: 4999 | F27: 6.82794e+16
E29: Coefficients | F29: Standard Error | G29: t Stat | H29: P-value | I29: Lower 95% | J29: Upper 95% | K29: Lower 95.0% | L29: Upper 95.0%
D30: Intercept | E30: -2014 | F30: 1.20949e-09 | G30: -1700000000000 | H30: 0 | I30: -2014 | J30: -2014 | K30: -2014 | L30: -2014
D31: X Variable 1 | E31: 533265 | F31: 2.40354e-11 | G31: 2.22e+16 | H31: 0 | I31: 533265 | J31: 533265 | K31: 533265 | L31: 533265
D32: X Variable 2 | E32: 533265 | F32: 3.94736e-11 | G32: 1.35e+16 | H32: 0 | I32: 533265 | J32: 533265 | K32: 533265 | L32: 533265
D33: X Variable 3 | E33: 1.73225e-10 | F33: 9.02135e-10 | G33: 0.192017 | H33: 0.847737 | I33: -1.59535e-09 | J33: 1.94e-09 | K33: -1.6e-09 | L33: 1.94e-09
D34: X Variable 4 | E34: -4.63704e-10 | F34: 4.43929e-10 | G34: -1.04455 | H34: 0.296284 | I34: -1.334e-09 | J34: 4.07e-10 | K34: -1.3e-09 | L34: 4.07e-10
D35: X Variable 5 | E35: -2.90703e-10 | F35: 1.10024e-10 | G35: -2.64218 | H35: 0.008263 | I35: -5.06398e-10 | J35: -7.5e-11 | K35: -5.1e-10 | L35: -7.5e-11
D36: X Variable 6 | E36: -2.76609e-10 | F36: 2.59822e-10 | G36: -1.06461 | H36: 0.287105 | I36: -7.85975e-10 | J36: 2.33e-10 | K36: -7.9e-10 | L36: 2.33e-10
D38: SUMMARY OUTPUT
D40: Regression Statistics
D41: Multiple R | E41: 1
D42: R Square | E42: 1
D43: Adjusted R Square | E43: 1
D44: Standard Error | E44: 2.64933e-08
D45: Observations | E45: 5000
D47: ANOVA
E48: df | F48: SS | G48: MS | H48: F | I48: Significance F
D49: Regression | E49: 6 | F49: 2.66105e+17 | G49: 4.44e+16 | H49: 6.32e+31 | I49: 0
D50: Residual | E50: 4993 | F50: 3.50455e-12 | G50: 7.02e-16
D51: Total | E51: 4999 | F51: 2.66105e+17
E53: Coefficients | F53: Standard Error | G53: t Stat | H53: P-value | I53: Lower 95% | J53: Upper 95% | K53: Lower 95.0% | L53: Upper 95.0%
...

Sheet Krishna
V1: Quarter | W1: Utilization (%) | X1: Inventory | Y1: A/P | Z1: COGS
V2: 2020 Q1 | W2: 0.9 | X2: 3675 | Y2: 5906 | Z2: 22250 | AC2: Utilization (%) | AD2: Inventory | AE2: A/P | AF2: COGS
V3: 2020 Q2 | W3: 0.74 | X3: 5420 | Y3: 4652 | Z3: 7074 | AB3: Mean | AC3: =AVERAGE(W2:W23) -> 0.89818182 | AD3: =AVERAGE(X2:X23) -> 6709.6364 | AE3: =AVERAGE(Y2:Y23) -> 11019.409 | AF3: =AVERAGE(Z2:Z23) -> 27589.636
V4: 2020 Q3 | W4: 0.8 | X4: 5357 | Y4: 5237 | Z4: 14266 | AB4: Standard Deviation | AC4: =STDEV(W2:W23) -> 0.063443741 | AD4: =STDEV(X2:X23) -> 1030.3452 | AE4: =STDEV(Y2:Y23) -> 3192.4928 | AF4: =STDEV(Z2:Z23) -> 8206.1506
V5: 2020 Q4 | W5: 0.81 | X5: 6038 | Y5: 6082 | Z5: 14962
V6: 2021 Q1 | W6: 0.77 | X6: 5908 | Y6: 9113 | Z6: 20648
V7: 2021 Q2 | W7: 0.9 | X7: 6103 | Y7: 10168 | Z7: 23921
V8: 2021 Q3 | W8: 0.91 | X8: 6227 | Y8: 9820 | Z8: 26362
V9: 2021 Q4 | W9: 0.96 | X9: 6265 | Y9: 12495 | Z9: 31914
V10: 2022 Q1 | W10: 0.89 | X10: 7174 | Y10: 15236 | Z10: 34905
V11: 2022 Q2 | W11: 0.94 | X11: 7147 | Y11: 16643 | Z11: 43318
V12: 2022 Q3 | W12: 0.95 | X12: 6628 | Y12: 13003 | Z12: 38597
V13: 2022 Q4 | W13: 0.97 | X13: 6752 | Y13: 12728 | Z13: 35145
V14: 2023 Q1 | W14: 0.93 | X14: 7455 | Y14: 10498 | Z14: 30060
V15: 2023 Q2 | W15: 0.94 | X15: 6961 | Y15: 10825 | Z15: 29421
V16: 2023 Q3 | W16: 0.95 | X16: 7513 | Y16: 13342 | Z16: 32495
... V23: 2025 Q2 | W23: 0.92 | X23: 7538 | Y23: 11499 | Z23: 26192

Sheet Krishna_V2
A1: Utilization | B1: 0.74 | C1: 0.77 | D1: 0.8 | E1: 0.81 | F1: 0.87 | G1: 0.89 | H1: 0.9 | I1: 0.91 | J1: 0.92 | K1: 0.93 | L1: 0.94 | M1: 0.95 | N1: 0.96 | O1: 0.97 | S1: Item | T1: Observations | U1: Correlation with Utilization | V1: Regression Slope | W1: Intercept | X1: R^2 | Y1: Standard Error
A2: Probability | B2: =1/22 -> 0.045454545 | C2: =1/22 -> 0.045454545 | D2: =1/22 -> 0.045454545 | E2: =1/22 -> 0.045454545 | F2: =1/22 -> 0.045454545 | G2: =2/22 -> 0.090909091 | H2: =3/22 -> 0.13636364 | I2: =1/22 -> 0.045454545 | J2: =1/22 -> 0.045454545 | K2: =1/22 -> 0.045454545 | L2: =5/22 -> 0.22727273 | M2: =2/22 -> 0.090909091 | N2: =1/22 -> 0.045454545 | O2: =1/22 -> 0.045454545 | S2: Inventory | T2: 21 | U2: 0.64899611 | V2: 7938.4225 | W2: -275.317 | X2: 0.421196 | Y2: 620.68411
A3: ummulative | B3: =B2 -> 0.045454545 | C3: =B3+C2 -> 0.090909091 | D3: =C3+D2 -> 0.13636364 | E3: =D3+E2 -> 0.18181818 | F3: =E3+F2 -> 0.22727273 | G3: =F3+G2 -> 0.31818182 | H3: =G3+H2 -> 0.45454545 | I3: =H3+I2 -> 0.5 | J3: =I3+J2 -> 0.54545455 | ... O3: =N3+O2 -> 1 | S3: A/P | T3: 22 | U3: 0.72023883 | V3: 36242.461 | W3: -21532.9 | X3: 0.518744 | Y3: 2269.4085
S4: COGS | T4: 22 | U4: 0.84122396 | V4: 108808.38 | W4: -70140.1 | X4: 0.7076577 | Y4: 4546.5286
A5: Iterations | B5: Rand | C5: Utilization | D5: Inventory | E5: Accounts Payable | F5: COGS | G5: Change in Inventory | H5: Change in Accounts Payable | I5: Change in COGS | J5: Net Working Capital | L5: Inventory | M5: Accounts Payable | N5: COGS | O5: Change in Inventory | P5: Change in Accounts Payable | Q5: Change in COGS | R5: Net Working Capital | S5: Utilization
A6: 1 | B6: =RAND() -> 0.66687677 | C6: =IF(B6<=$B$3, $B$1, IF(B6<=$C$3, $C$1, IF(B6<=$D$3, $D$1, IF(B6<=$E$3, $E$1, IF(B6<=$F$3, $F$1, IF(B6<=$G$3, $G$1, IF(B6<=$H$3, $H$1, IF(B6<=$I$3, $I$1, IF(B6<=$J$3, $J$1, IF(B6<=$K$3, $K$1, IF(B6<=$L$3, $L$1, IF(B6<=$M$3, $M$1, IF(B6<=$N$3, $N$1, IF(B6<=$O$3, $O$1, "Error")))))))))))))) -> 0.94 | D6: =$W$2+$V$2*C6+$Y$2*_xlfn.NORM.INV(RAND(),0,1) -> 6923.0784 | E6: =MAX(0,$W$3+$V$3*C6+$Y$3*_xlfn.NORM.INV(RAND(),0,1)) -> 16482.615 | F6: =$W$4+$V$4*C6+$Y$4*_xlfn.NORM.INV(RAND(),0,1) -> 39059.481 | G6: =D6-Krishna!$AD$3 -> 213.44208 | H6: =E6-Krishna!$AE$3 -> 5463.2062 | I6: =F6-Krishna!$AF$3 -> 11469.845 | J6: =D6-E6 -> -9559.5368 | K6: Average | L6: =AVERAGE(D6:D5005) -> 6855.5269 | M6: =AVERAGE(E6:E5005) -> 10985.117 | N6: =AVERAGE(F6:F5005) -> 27558.865 | O6: =AVERAGE(G6:G5005) -> 145.89054 | P6: =AVERAGE(H6:H5005) -> -34.292093 | Q6: =AVERAGE(I6:I5005) -> -30.770984 | R6: =AVERAGE(J6:J5005) -> -4129.5901 | S6: =AVERAGE(C6:C5005) -> 0.897636
A7: 2 | B7: =RAND() -> 0.54678462 | C7: =IF(B7<=$B$3, $B$1, IF(B7<=$C$3, $C$1, IF(B7<=$D$3, $D$1, IF(B7<=$E$3, $E$1, IF(B7<=$F$3, $F$1, IF(B7<=$G$3, $G$1, IF(B7<=$H$3, $H$1, IF(B7<=$I$3, $I$1, IF(B7<=$J$3, $J$1, IF(B7<=$K$3, $K$1, IF(B7<=$L$3, $L$1, IF(B7<=$M$3, $M$1, IF(B7<=$N$3, $N$1, IF(B7<=$O$3, $O$1, "Error")))))))))))))) -> 0.93 | D7: =$W$2+$V$2*C7+$Y$2*_xlfn.NORM.INV(RAND(),0,1) -> 6657.9657 | E7: =MAX(0,$W$3+$V$3*C7+$Y$3*_xlfn.NORM.INV(RAND(),0,1)) -> 15418.07 | F7: =$W$4+$V$4*C7+$Y$4*_xlfn.NORM.INV(RAND(),0,1) -> 28426.426 | G7: =D7-Krishna!$AD$3 -> -51.670624 | H7: =E7-Krishna!$AE$3 -> 4398.6608 | I7: =F7-Krishna!$AF$3 -> 836.78914 | J7: =D7-E7 -> -8760.1041 | K7: Median - Normal | L7: =MEDIAN(D6:D5005) -> 6897.126 | M7: =MEDIAN(E6:E5005) -> 11298.984 | N7: =MEDIAN(F6:F5005) -> 29018.003 | O7: =MEDIAN(G6:G5005) -> 187.4896 | P7: =MEDIAN(H6:H5005) -> 279.57508 | Q7: =MEDIAN(I6:I5005) -> 1428.3664 | R7: =MEDIAN(J6:J5005) -> -4288.0676 | S7: =MEDIAN(C6:C5005) -> 0.92
A8: 3 | B8: =RAND() -> 0.33476222 | C8: =IF(B8<=$B$3, $B$1, IF(B8<=$C$3, $C$1, IF(B8<=$D$3, $D$1, IF(B8<=$E$3, $E$1, IF(B8<=$F$3, $F$1, IF(B8<=$G$3, $G$1, IF(B8<=$H$3, $H$1, IF(B8<=$I$3, $I$1, IF(B8<=$J$3, $J$1, IF(B8<=$K$3, $K$1, IF(B8<=$L$3, $L$1, IF(B8<=$M$3, $M$1, IF(B8<=$N$3, $N$1, IF(B8<=$O$3, $O$1, "Error")))))))))))))) -> 0.9 | D8: =$W$2+$V$2*C8+$Y$2*_xlfn.NORM.INV(RAND(),0,1) -> 6080.4995 | E8: =MAX(0,$W$3+$V$3*C8+$Y$3*_xlfn.NORM.INV(RAND(),0,1)) -> 11424.262 | F8: =$W$4+$V$4*C8+$Y$4*_xlfn.NORM.INV(RAND(),0,1) -> 33866.958 | G8: =D8-Krishna!$AD$3 -> -629.13689 | H8: =E8-Krishna!$AE$3 -> 404.85325 | I8: =F8-Krishna!$AF$3 -> 6277.3214 | J8: =D8-E8 -> -5343.7629 | K8: Percentile (5th) - Worst | L8: =_xlfn.PERCENTILE.EXC(D6:D5005, 0.05) -> 5451.5933 | M8: =_xlfn.PERCENTILE.EXC(E6:E5005, 0.05) -> 5199.8986 | N8: =_xlfn.PERCENTILE.EXC(F6:F5005, 0.05) -> 11660.135 | O8: =_xlfn.PERCENTILE.EXC(G6:G5005, 0.05) -> -1258.043 | P8: =_xlfn.PERCENTILE.EXC(H6:H5005, 0.05) -> -5819.5105 | Q8: =_xlfn.PERCENTILE.EXC(I6:I5005, 0.05) -> -15929.501 | R8: =_xlfn.PERCENTILE.INC(J6:J5005,0.05) -> -8648.0595 | S8: =_xlfn.PERCENTILE.INC(C6:C5005,0.05) -> 0.77
A9: 4 | B9: =RAND() -> 0.16938606 | C9: =IF(B9<=$B$3, $B$1, IF(B9<=$C$3, $C$1, IF(B9<=$D$3, $D$1, IF(B9<=$E$3, $E$1, IF(B9<=$F$3, $F$1, IF(B9<=$G$3, $G$1, IF(B9<=$H$3, $H$1, IF(B9<=$I$3, $I$1, IF(B9<=$J$3, $J$1, IF(B9<=$K$3, $K$1, IF(B9<=$L$3, $L$1, IF(B9<=$M$3, $M$1, IF(B9<=$N$3, $N$1, IF(B9<=$O$3, $O$1, "Error")))))))))))))) -> 0.81 | D9: =$W$2+$V$2*C9+$Y$2*_xlfn.NORM.INV(RAND(),0,1) -> 6084.7696 | E9: =MAX(0,$W$3+$V$3*C9+$Y$3*_xlfn.NORM.INV(RAND(),0,1)) -> 8054.4621 | F9: =$W$4+$V$4*C9+$Y$4*_xlfn.NORM.INV(RAND(),0,1) -> 21609.077 | G9: =D9-Krishna!$AD$3 -> -624.86679 | H9: =E9-Krishna!$AE$3 -> -2964.947 | I9: =F9-Krishna!$AF$3 -> -5980.5595 | J9: =D9-E9 -> -1969.6925 | K9: Percentile (95th) - Best | L9: =_xlfn.PERCENTILE.EXC(D6:D5005, 0.95) -> 8065.4238 | M9: =_xlfn.PERCENTILE.EXC(E6:E5005, 0.95) -> 15685.597 | N9: =_xlfn.PERCENTILE.EXC(F6:F5005, 0.95) -> 38708.33 | O9: =_xlfn.PERCENTILE.EXC(G6:G5005, 0.95) -> 1355.7875 | P9: =_xlfn.PERCENTILE.EXC(H6:H5005, 0.95) -> 4666.1875 | Q9: =_xlfn.PERCENTILE.EXC(I6:I5005, 0.95) -> 11118.693 | R9: =_xlfn.PERCENTILE.INC(J6:J5005,0.95) -> 896.47307 | S9: =_xlfn.PERCENTILE.INC(C6:C5005,0.95) -> 0.96
A10: 5 | B10: =RAND() -> 0.750507 | C10: =IF(B10<=$B$3, $B$1, IF(B10<=$C$3, $C$1, IF(B10<=$D$3, $D$1, IF(B10<=$E$3, $E$1, IF(B10<=$F$3, $F$1, IF(B10<=$G$3, $G$1, IF(B10<=$H$3, $H$1, IF(B10<=$I$3, $I$1, IF(B10<=$J$3, $J$1, IF(B10<=$K$3, $K$1, IF(B10<=$L$3, $L$1, IF(B10<=$M$3, $M$1, IF(B10<=$N$3, $N$1, IF(B10<=$O$3, $O$1, "Error")))))))))))))) -> 0.94 | D10: =$W$2+$V$2*C10+$Y$2*_xlfn.NORM.INV(RAND(),0,1) -> 7071.8645 | E10: =MAX(0,$W$3+$V$3*C10+$Y$3*_xlfn.NORM.INV(RAND(),0,1)) -> 13840.617 | F10: =$W$4+$V$4*C10+$Y$4*_xlfn.NORM.INV(RAND(),0,1) -> 34046.199 | G10: =D10-Krishna!$AD$3 -> 362.22811 | H10: =E10-Krishna!$AE$3 -> 2821.2074 | I10: =F10-Krishna!$AF$3 -> 6456.5622 | J10: =D10-E10 -> -6768.7521 | K10: Minimum | L10: =MIN(D6:D5005) -> 3701.826 | M10: =MIN(E6:E5005) -> 0 | N10: =MIN(F6:F5005) -> -3188.1612 | O10: =MIN(G6:G5005) -> -3007.8103 | P10: =MIN(H6:H5005) -> -11019.409 | Q10: =MIN(I6:I5005) -> -30777.798 | R10: =MIN(J6:J5005) -> -14567.278 | S10: =MIN(C6:C5005) -> 0.74
A11: 6 | B11: =RAND() -> 0.42669591 | C11: =IF(B11<=$B$3, $B$1, IF(B11<=$C$3, $C$1, IF(B11<=$D$3, $D$1, IF(B11<=$E$3, $E$1, IF(B11<=$F$3, $F$1, IF(B11<=$G$3, $G$1, IF(B11<=$H$3, $H$1, IF(B11<=$I$3, $I$1, IF(B11<=$J$3, $J$1, IF(B11<=$K$3, $K$1, IF(B11<=$L$3, $L$1, IF(B11<=$M$3, $M$1, IF(B11<=$N$3, $N$1, IF(B11<=$O$3, $O$1, "Error")))))))))))))) -> 0.9 | D11: =$W$2+$V$2*C11+$Y$2*_xlfn.NORM.INV(RAND(),0,1) -> 7195.2533 | E11: =MAX(0,$W$3+$V$3*C11+$Y$3*_xlfn.NORM.INV(RAND(),0,1)) -> 8197.1828 | F11: =$W$4+$V$4*C11+$Y$4*_xlfn.NORM.INV(RAND(),0,1) -> 28404.194 | G11: =D11-Krishna!$AD$3 -> 485.61691 | H11: =E11-Krishna!$AE$3 -> -2822.2263 | I11: =F11-Krishna!$AF$3 -> 814.55763 | J11: =D11-E11 -> -1001.9295 | K11: Maximum | L11: =MAX(D6:D5005) -> 9609.6816 | M11: =MAX(E6:E5005) -> 22553.022 | N11: =MAX(F6:F5005) -> 47282.847 | O11: =MAX(G6:G5005) -> 2900.0452 | P11: =MAX(H6:H5005) -> 11533.613 | Q11: =MAX(I6:I5005) -> 19693.211 | R11: =MAX(J6:J5005) -> 6518.1214 | S11: =MAX(C6:C5005) -> 0.97
A12: 7 | B12: =RAND() -> 0.81529699 | C12: =IF(B12<=$B$3, $B$1, IF(B12<=$C$3, $C$1, IF(B12<=$D$3, $D$1, IF(B12<=$E$3, $E$1, IF(B12<=$F$3, $F$1, IF(B12<=$G$3, $G$1, IF(B12<=$H$3, $H$1, IF(B12<=$I$3, $I$1, IF(B12<=$J$3, $J$1, IF(B12<=$K$3, $K$1, IF(B12<=$L$3, $L$1, IF(B12<=$M$3, $M$1, IF(B12<=$N$3, $N$1, IF(B12<=$O$3, $O$1, "Error")))))))))))))) -> 0.94 | D12: =$W$2+$V$2*C12+$Y$2*_xlfn.NORM.INV(RAND(),0,1) -> 7194.7633 | E12: =MAX(0,$W$3+$V$3*C12+$Y$3*_xlfn.NORM.INV(RAND(),0,1)) -> 11930.307 | F12: =$W$4+$V$4*C12+$Y$4*_xlfn.NORM.INV(RAND(),0,1) -> 36512.009 | G12: =D12-Krishna!$AD$3 -> 485.12697 | H12: =E12-Krishna!$AE$3 -> 910.89833 | I12: =F12-Krishna!$AF$3 -> 8922.373 | J12: =D12-E12 -> -4735.5441 | K12: Standard Deviation | L12: =STDEV(D6:D5005) -> 791.51393 | M12: =STDEV(E6:E5005) -> 3150.7941 | N12: =STDEV(F6:F5005) -> 8114.963 | O12: =STDEV(G6:G5005) -> 791.51393 | P12: =STDEV(H6:H5005) -> 3150.7941 | Q12: =STDEV(I6:I5005) -> 8114.963 | R12: =STDEV(J6:J5005) -> 2893.5443 | S12: =STDEV(C6:C5005) -> 0.062221747
A13: 8 | B13: =RAND() -> 0.63340414 | C13: =IF(B13<=$B$3, $B$1, IF(B13<=$C$3, $C$1, IF(B13<=$D$3, $D$1, IF(B13<=$E$3, $E$1, IF(B13<=$F$3, $F$1, IF(B13<=$G$3, $G$1, IF(B13<=$H$3, $H$1, IF(B13<=$I$3, $I$1, IF(B13<=$J$3, $J$1, IF(B13<=$K$3, $K$1, IF(B13<=$L$3, $L$1, IF(B13<=$M$3, $M$1, IF(B13<=$N$3, $N$1, IF(B13<=$O$3, $O$1, "Error")))))))))))))) -> 0.94 | D13: =$W$2+$V$2*C13+$Y$2*_xlfn.NORM.INV(RAND(),0,1) -> 8257.2846 | E13: =MAX(0,$W$3+$V$3*C13+$Y$3*_xlfn.NORM.INV(RAND(),0,1)) -> 15890.032 | F13: =$W$4+$V$4*C13+$Y$4*_xlfn.NORM.INV(RAND(),0,1) -> 33108.199 | G13: =D13-Krishna!$AD$3 -> 1547.6483 | H13: =E13-Krishna!$AE$3 -> 4870.6232 | I13: =F13-Krishna!$AF$3 -> 5518.5622 | J13: =D13-E13 -> -7632.7476
A14: 9 | B14: =RAND() -> 0.26162169 | C14: =IF(B14<=$B$3, $B$1, IF(B14<=$C$3, $C$1, IF(B14<=$D$3, $D$1, IF(B14<=$E$3, $E$1, IF(B14<=$F$3, $F$1, IF(B14<=$G$3, $G$1, IF(B14<=$H$3, $H$1, IF(B14<=$I$3, $I$1, IF(B14<=$J$3, $J$1, IF(B14<=$K$3, $K$1, IF(B14<=$L$3, $L$1, IF(B14<=$M$3, $M$1, IF(B14<=$N$3, $N$1, IF(B14<=$O$3, $O$1, "Error")))))))))))))) -> 0.89 | D14: =$W$2+$V$2*C14+$Y$2*_xlfn.NORM.INV(RAND(),0,1) -> 7490.9959 | E14: =MAX(0,$W$3+$V$3*C14+$Y$3*_xlfn.NORM.INV(RAND(),0,1)) -> 14251.489 | F14: =$W$4+$V$4*C14+$Y$4*_xlfn.NORM.INV(RAND(),0,1) -> 27753.796 | G14: =D14-Krishna!$AD$3 -> 781.35951 | H14: =E14-Krishna!$AE$3 -> 3232.0803 | I14: =F14-Krishna!$AF$3 -> 164.15927 | J14: =D14-E14 -> -6760.4935
A15: 10 | B15: =RAND() -> 0.21911209 | C15: =IF(B15<=$B$3, $B$1, IF(B15<=$C$3, $C$1, IF(B15<=$D$3, $D$1, IF(B15<=$E$3, $E$1, IF(B15<=$F$3, $F$1, IF(B15<=$G$3, $G$1, IF(B15<=$H$3, $H$1, IF(B15<=$I$3, $I$1, IF(B15<=$J$3, $J$1, IF(B15<=$K$3, $K$1, IF(B15<=$L$3, $L$1, IF(B15<=$M$3, $M$1, IF(B15<=$N$3, $N$1, IF(B15<=$O$3, $O$1, "Error")))))))))))))) -> 0.87 | D15: =$W$2+$V$2*C15+$Y$2*_xlfn.NORM.INV(RAND(),0,1) -> 6541.4776 | E15: =MAX(0,$W$3+$V$3*C15+$Y$3*_xlfn.NORM.INV(RAND(),0,1)) -> 9315.2432 | F15: =$W$4+$V$4*C15+$Y$4*_xlfn.NORM.INV(RAND(),0,1) -> 27947.062 | G15: =D15-Krishna!$AD$3 -> -168.15881 | H15: =E15-Krishna!$AE$3 -> -1704.1659 | I15: =F15-Krishna!$AF$3 -> 357.42561 | J15: =D15-E15 -> -2773.7657
A16: 11 | B16: =RAND() -> 0.8580307 | C16: =IF(B16<=$B$3, $B$1, IF(B16<=$C$3, $C$1, IF(B16<=$D$3, $D$1, IF(B16<=$E$3, $E$1, IF(B16<=$F$3, $F$1, IF(B16<=$G$3, $G$1, IF(B16<=$H$3, $H$1, IF(B16<=$I$3, $I$1, IF(B16<=$J$3, $J$1, IF(B16<=$K$3, $K$1, IF(B16<=$L$3, $L$1, IF(B16<=$M$3, $M$1, IF(B16<=$N$3, $N$1, IF(B16<=$O$3, $O$1, "Error")))))))))))))) -> 0.95 | D16: =$W$2+$V$2*C16+$Y$2*_xlfn.NORM.INV(RAND(),0,1) -> 6445.5437 | E16: =MAX(0,$W$3+$V$3*C16+$Y$3*_xlfn.NORM.INV(RAND(),0,1)) -> 13925.856 | F16: =$W$4+$V$4*C16+$Y$4*_xlfn.NORM.INV(RAND(),0,1) -> 40938.701 | G16: =D16-Krishna!$AD$3 -> -264.09264 | H16: =E16-Krishna!$AE$3 -> 2906.4467 | I16: =F16-Krishna!$AF$3 -> 13349.064 | J16: =D16-E16 -> -7480.3121
A17: 12 | B17: =RAND() -> 0.77948991 | C17: =IF(B17<=$B$3, $B$1, IF(B17<=$C$3, $C$1, IF(B17<=$D$3, $D$1, IF(B17<=$E$3, $E$1, IF(B17<=$F$3, $F$1, IF(B17<=$G$3, $G$1, IF(B17<=$H$3, $H$1, IF(B17<=$I$3, $I$1, IF(B17<=$J$3, $J$1, IF(B17<=$K$3, $K$1, IF(B17<=$L$3, $L$1, IF(B17<=$M$3, $M$1, IF(B17<=$N$3, $N$1, IF(B17<=$O$3, $O$1, "Error")))))))))))))) -> 0.94 | D17: =$W$2+$V$2*C17+$Y$2*_xlfn.NORM.INV(RAND(),0,1) -> 7210.9273 | E17: =MAX(0,$W$3+$V$3*C17+$Y$3*_xlfn.NORM.INV(RAND(),0,1)) -> 12056.125 | F17: =$W$4+$V$4*C17+$Y$4*_xlfn.NORM.INV(RAND(),0,1) -> 29644.944 | G17: =D17-Krishna!$AD$3 -> 501.29095 | H17: =E17-Krishna!$AE$3 -> 1036.7159 | I17: =F17-Krishna!$AF$3 -> 2055.3072 | J17: =D17-E17 -> -4845.1977
A18: 13 | B18: =RAND() -> 0.093271543 | C18: =IF(B18<=$B$3, $B$1, IF(B18<=$C$3, $C$1, IF(B18<=$D$3, $D$1, IF(B18<=$E$3, $E$1, IF(B18<=$F$3, $F$1, IF(B18<=$G$3, $G$1, IF(B18<=$H$3, $H$1, IF(B18<=$I$3, $I$1, IF(B18<=$J$3, $J$1, IF(B18<=$K$3, $K$1, IF(B18<=$L$3, $L$1, IF(B18<=$M$3, $M$1, IF(B18<=$N$3, $N$1, IF(B18<=$O$3, $O$1, "Error")))))))))))))) -> 0.8 | D18: =$W$2+$V$2*C18+$Y$2*_xlfn.NORM.INV(RAND(),0,1) -> 5281.3106 | E18: =MAX(0,$W$3+$V$3*C18+$Y$3*_xlfn.NORM.INV(RAND(),0,1)) -> 7734.5615 | F18: =$W$4+$V$4*C18+$Y$4*_xlfn.NORM.INV(RAND(),0,1) -> 20825.914 | G18: =D18-Krishna!$AD$3 -> -1428.3258 | H18: =E18-Krishna!$AE$3 -> -3284.8476 | I18: =F18-Krishna!$AF$3 -> -6763.7219 | J18: =D18-E18 -> -2453.2508
A19: 14 | B19: =RAND() -> 0.82111262 | C19: =IF(B19<=$B$3, $B$1, IF(B19<=$C$3, $C$1, IF(B19<=$D$3, $D$1, IF(B19<=$E$3, $E$1, IF(B19<=$F$3, $F$1, IF(B19<=$G$3, $G$1, IF(B19<=$H$3, $H$1, IF(B19<=$I$3, $I$1, IF(B19<=$J$3, $J$1, IF(B19<=$K$3, $K$1, IF(B19<=$L$3, $L$1, IF(B19<=$M$3, $M$1, IF(B19<=$N$3, $N$1, IF(B19<=$O$3, $O$1, "Error")))))))))))))) -> 0.95 | D19: =$W$2+$V$2*C19+$Y$2*_xlfn.NORM.INV(RAND(),0,1) -> 8426.1229 | E19: =MAX(0,$W$3+$V$3*C19+$Y$3*_xlfn.NORM.INV(RAND(),0,1)) -> 15510.095 | F19: =$W$4+$V$4*C19+$Y$4*_xlfn.NORM.INV(RAND(),0,1) -> 28784.121 | G19: =D19-Krishna!$AD$3 -> 1716.4865 | H19: =E19-Krishna!$AE$3 -> 4490.686 | I19: =F19-Krishna!$AF$3 -> 1194.4851 | J19: =D19-E19 -> -7083.9721
A20: 15 | B20: =RAND() -> 0.39831104 | C20: =IF(B20<=$B$3, $B$1, IF(B20<=$C$3, $C$1, IF(B20<=$D$3, $D$1, IF(B20<=$E$3, $E$1, IF(B20<=$F$3, $F$1, IF(B20<=$G$3, $G$1, IF(B20<=$H$3, $H$1, IF(B20<=$I$3, $I$1, IF(B20<=$J$3, $J$1, IF(B20<=$K$3, $K$1, IF(B20<=$L$3, $L$1, IF(B20<=$M$3, $M$1, IF(B20<=$N$3, $N$1, IF(B20<=$O$3, $O$1, "Error")))))))))))))) -> 0.9 | D20: =$W$2+$V$2*C20+$Y$2*_xlfn.NORM.INV(RAND(),0,1) -> 7165.6179 | E20: =MAX(0,$W$3+$V$3*C20+$Y$3*_xlfn.NORM.INV(RAND(),0,1)) -> 12121.178 | F20: =$W$4+$V$4*C20+$Y$4*_xlfn.NORM.INV(RAND(),0,1) -> 31903.577 | G20: =D20-Krishna!$AD$3 -> 455.98151 | H20: =E20-Krishna!$AE$3 -> 1101.7686 | I20: =F20-Krishna!$AF$3 -> 4313.9402 | J20: =D20-E20 -> -4955.5598
A21: 16 | B21: =RAND() -> 0.85340964 | C21: =IF(B21<=$B$3, $B$1, IF(B21<=$C$3, $C$1, IF(B21<=$D$3, $D$1, IF(B21<=$E$3, $E$1, IF(B21<=$F$3, $F$1, IF(B21<=$G$3, $G$1, IF(B21<=$H$3, $H$1, IF(B21<=$I$3, $I$1, IF(B21<=$J$3, $J$1, IF(B21<=$K$3, $K$1, IF(B21<=$L$3, $L$1, IF(B21<=$M$3, $M$1, IF(B21<=$N$3, $N$1, IF(B21<=$O$3, $O$1, "Error")))))))))))))) -> 0.95 | D21: =$W$2+$V$2*C21+$Y$2*_xlfn.NORM.INV(RAND(),0,1) -> 7921.6786 | E21: =MAX(0,$W$3+$V$3*C21+$Y$3*_xlfn.NORM.INV(RAND(),0,1)) -> 12634.81 | F21: =$W$4+$V$4*C21+$Y$4*_xlfn.NORM.INV(RAND(),0,1) -> 39881.456 | G21: =D21-Krishna!$AD$3 -> 1212.0422 | H21: =E21-Krishna!$AE$3 -> 1615.4005 | I21: =F21-Krishna!$AF$3 -> 12291.82 | J21: =D21-E21 -> -4713.131
A22: 17 | B22: =RAND() -> 0.92150471 | C22: =IF(B22<=$B$3, $B$1, IF(B22<=$C$3, $C$1, IF(B22<=$D$3, $D$1, IF(B22<=$E$3, $E$1, IF(B22<=$F$3, $F$1, IF(B22<=$G$3, $G$1, IF(B22<=$H$3, $H$1, IF(B22<=$I$3, $I$1, IF(B22<=$J$3, $J$1, IF(B22<=$K$3, $K$1, IF(B22<=$L$3, $L$1, IF(B22<=$M$3, $M$1, IF(B22<=$N$3, $N$1, IF(B22<=$O$3, $O$1, "Error")))))))))))))) -> 0.96 | D22: =$W$2+$V$2*C22+$Y$2*_xlfn.NORM.INV(RAND(),0,1) -> 8010.7795 | E22: =MAX(0,$W$3+$V$3*C22+$Y$3*_xlfn.NORM.INV(RAND(),0,1)) -> 15658.298 | F22: =$W$4+$V$4*C22+$Y$4*_xlfn.NORM.INV(RAND(),0,1) -> 37304.696 | G22: =D22-Krishna!$AD$3 -> 1301.1431 | H22: =E22-Krishna!$AE$3 -> 4638.8889 | I22: =F22-Krishna!$AF$3 -> 9715.0593 | J22: =D22-E22 -> -7647.5185
A23: 18 | B23: =RAND() -> 0.56482878 | C23: =IF(B23<=$B$3, $B$1, IF(B23<=$C$3, $C$1, IF(B23<=$D$3, $D$1, IF(B23<=$E$3, $E$1, IF(B23<=$F$3, $F$1, IF(B23<=$G$3, $G$1, IF(B23<=$H$3, $H$1, IF(B23<=$I$3, $I$1, IF(B23<=$J$3, $J$1, IF(B23<=$K$3, $K$1, IF(B23<=$L$3, $L$1, IF(B23<=$M$3, $M$1, IF(B23<=$N$3, $N$1, IF(B23<=$O$3, $O$1, "Error")))))))))))))) -> 0.93 | D23: =$W$2+$V$2*C23+$Y$2*_xlfn.NORM.INV(RAND(),0,1) -> 7593.6247 | E23: =MAX(0,$W$3+$V$3*C23+$Y$3*_xlfn.NORM.INV(RAND(),0,1)) -> 12276.442 | F23: =$W$4+$V$4*C23+$Y$4*_xlfn.NORM.INV(RAND(),0,1) -> 30017.619 | G23: =D23-Krishna!$AD$3 -> 883.98831 | H23: =E23-Krishna!$AE$3 -> 1257.0331 | I23: =F23-Krishna!$AF$3 -> 2427.9829 | J23: =D23-E23 -> -4682.8175
A24: 19 | B24: =RAND() -> 0.62839048 | C24: =IF(B24<=$B$3, $B$1, IF(B24<=$C$3, $C$1, IF(B24<=$D$3, $D$1, IF(B24<=$E$3, $E$1, IF(B24<=$F$3, $F$1, IF(B24<=$G$3, $G$1, IF(B24<=$H$3, $H$1, IF(B24<=$I$3, $I$1, IF(B24<=$J$3, $J$1, IF(B24<=$K$3, $K$1, IF(B24<=$L$3, $L$1, IF(B24<=$M$3, $M$1, IF(B24<=$N$3, $N$1, IF(B24<=$O$3, $O$1, "Error")))))))))))))) -> 0.94 | D24: =$W$2+$V$2*C24+$Y$2*_xlfn.NORM.INV(RAND(),0,1) -> 7820.4527 | E24: =MAX(0,$W$3+$V$3*C24+$Y$3*_xlfn.NORM.INV(RAND(),0,1)) -> 11016.307 | F24: =$W$4+$V$4*C24+$Y$4*_xlfn.NORM.INV(RAND(),0,1) -> 20785.49 | G24: =D24-Krishna!$AD$3 -> 1110.8163 | H24: =E24-Krishna!$AE$3 -> -3.1016504 | I24: =F24-Krishna!$AF$3 -> -6804.1463 | J24: =D24-E24 -> -3195.8547
... A5005: 5000 | B5005: =RAND() -> 0.82611502 | C5005: =IF(B5005<=$B$3, $B$1, IF(B5005<=$C$3, $C$1, IF(B5005<=$D$3, $D$1, IF(B5005<=$E$3, $E$1, IF(B5005<=$F$3, $F$1, IF(B5005<=$G$3, $G$1, IF(B5005<=$H$3, $H$1, IF(B5005<=$I$3, $I$1, IF(B5005<=$J$3, $J$1, IF(B5005<=$K$3, $K$1, IF(B5005<=$L$3, $L$1, IF(B5005<=$M$3, $M$1, IF(B5005<=$N$3, $N$1, IF(B5005<=$O$3, $O$1, "Error")))))))))))))) -> 0.95 | D5005: =$W$2+$V$2*C5005+$Y$2*_xlfn.NORM.INV(RAND(),0,1) -> 7313.9184 | E5005: =MAX(0,$W$3+$V$3*C5005+$Y$3*_xlfn.NORM.INV(RAND(),0,1)) -> 12258.57 | F5005: =$W$4+$V$4*C5005+$Y$4*_xlfn.NORM.INV(RAND(),0,1) -> 28291.218 | G5005: =D5005-Krishna!$AD$3 -> 604.282 | H5005: =E5005-Krishna!$AE$3 -> 1239.1606 | I5005: =F5005-Krishna!$AF$3 -> 701.58203 | J5005: =D5005-E5005 -> -4944.6513

Sheet Ramita
A1: Valero Environmental & Regulatory Risk Model | D1: Old data set | E1: Quarter - Year | F1: RIN: | G1: LCFS | H1: Carbon allowance | J1: Simulation Results | L1: new data set | M1: Quarter - Year | N1: RIN price ($) | O1: LCFS price ($) | P1: Carbon allowance ($)
E2: Q1 2024 | F2: 0.58 | G2: 63.55 | H2: 41.76 | M2: Q1 2020 | N2: 0.46 | O2: 206.03 | P2: 12
A3: Risk Driver Parameters | E3: Q2 2024 | F3: 0.51 | G3: 51.29 | H3: 37.02 | J3: Metric | K3: Value | M3: Q2 2020 | N3: 0.54 | O3: 201.01 | P3: 14
A4: Driver | B4: Mean (μ) | C4: Std Dev (σ) | D4: Sensitivity | E4: Q3 2024 | F4: 0.6 | G4: 53.65 | H4: 30.24 | J4: Iterations | K4: =COUNT(H9:H4343) -> 1000 | M4: Q3 2020 | N4: 0.67 | O4: 195.6 | P4: 16
A5: RIN Price | B5: =AVERAGE(N2:N23) -> 1.1095455 | C5: =_xlfn.STDEV.S(N2:N23) -> 0.4636961 | D5: 50 | E5: Q4 2024 | F5: 0.84 | G5: 68.71 | H5: 31.91 | J5: Expected Impact | K5: =AVERAGE(H9:H1007) -> 279.7421 | M5: Q4 2020 | N5: 0.88 | O5: 197.83 | P5: 18
A6: LCFS Price | B6: =AVERAGE(O2:O23) -> 116.88364 | C6: =_xlfn.STDEV.S(O2:O23) -> 61.173589 | D6: 25 | E6: Q1 2025 | F6: 0.79 | G6: 66.17 | H6: 36.58 | J6: 5% VaR (95% Confidence) | K6: =PERCENTILE(H9:H1007, 0.05) -> -477.50787 | M6: Q1 2021 | N6: 1.18 | O6: 195.3 | P6: 19
A7: Carbon Price | B7: =AVERAGE(P2:P23) -> 46.136364 | C7: =_xlfn.STDEV.S(P2:P23) -> 27.085922 | D7: 100 | E7: Q2 2025 | F7: 0.94 | G7: 52.36 | H7: 42 | J7: Worst Case | K7: =MIN(H9:H1007) -> -804.98351 | M7: Q2 2021 | N7: 1.71 | O7: 184.82 | P7: 20
A8: Iteration | B8: RIN Price | C8: LCFS Price | D8: Carbon Price | E8: change in Operating Income | F8: PP&E Impairment | G8: ARO Increase | H8: Total Impact | J8: Best Case | K8: =MAX(H9:H1007) -> 9119.593 | M8: Q3 2021 | N8: 1.18 | O8: 195.3 | P8: 22
A9: 1 | B9: =_xlfn.LOGNORM.INV(RAND(), $O$31, $O$32) -> 0.99096628 | C9: =_xlfn.LOGNORM.INV(RAND(), $O$28, $O$29) -> 59.790874 | D9: =_xlfn.LOGNORM.INV(RAND(), $O$25, $O$26) -> 10.706137 | E9: =((B9-$B$5)/0.1)*$D$5 + ((C9-$B$6)/10)*$D$6 + ((D9-$B$7)/10)*$D$7 -> -556.32376 | F9: =IF(OR(B9<0.4, D9>50), 150, 0) -> 0 | G9: =(D9/10)*D7 -> 107.06137 | H9: =E9+F9+G9 -> -449.26239 | J9: Std Deviation | K9: =STDEV(H9:H1007) -> 748.48635 | M9: Q4 2021 | N9: 1.49 | O9: 155.24 | P9: 25
A10: 2 | B10: =_xlfn.LOGNORM.INV(RAND(), $O$31, $O$32) -> 1.0315189 | C10: =_xlfn.LOGNORM.INV(RAND(), $O$28, $O$29) -> 98.238185 | D10: =_xlfn.LOGNORM.INV(RAND(), $O$25, $O$26) -> 25.750895 | E10: =((B10-$B$5)/0.1)*$D$5 + ((C10-$B$6)/10)*$D$6 + ((D10-$B$7)/10)*$D$7 -> -289.4816 | F10: =IF(OR(B10<0.4, D10>50), 150, 0) -> 0 | G10: =(D10/10)*D7 -> 257.50895 | H10: =E10+F10+G10 -> -31.972653 | M10: Q1 2022 | N10: 1.43 | O10: 138.63 | P10: 29
A11: 3 | B11: =_xlfn.LOGNORM.INV(RAND(), $O$31, $O$32) -> 2.2953264 | C11: =_xlfn.LOGNORM.INV(RAND(), $O$28, $O$29) -> 75.096802 | D11: =_xlfn.LOGNORM.INV(RAND(), $O$25, $O$26) -> 8.6794952 | E11: =((B11-$B$5)/0.1)*$D$5 + ((C11-$B$6)/10)*$D$6 + ((D11-$B$7)/10)*$D$7 -> 113.8547 | F11: =IF(OR(B11<0.4, D11>50), 150, 0) -> 0 | G11: =(D11/10)*D9 -> 9.2923866 | H11: =E11+F11+G11 -> 123.14709 | J11: Correlation | M11: Q2 2022 | N11: 1.7 | O11: 104.3 | P11: 32
A12: 4 | B12: =_xlfn.LOGNORM.INV(RAND(), $O$31, $O$32) -> 1.3303515 | C12: =_xlfn.LOGNORM.INV(RAND(), $O$28, $O$29) -> 72.545058 | D12: =_xlfn.LOGNORM.INV(RAND(), $O$25, $O$26) -> 44.784415 | E12: =((B12-$B$5)/0.1)*$D$5 + ((C12-$B$6)/10)*$D$6 + ((D12-$B$7)/10)*$D$7 -> -13.962915 | F12: =IF(OR(B12<0.4, D12>50), 150, 0) -> 0 | G12: =(D12/10)*D10 -> 115.32388 | H12: =E12+F12+G12 -> 101.36096 | J12: =CORREL(B9:B1008,D9:D1008) -> 0.00098256983 | M12: Q3 2022 | N12: 1.71 | O12: 86.21 | P12: 35
A13: 5 | B13: =_xlfn.LOGNORM.INV(RAND(), $O$31, $O$32) -> 0.91137238 | C13: =_xlfn.LOGNORM.INV(RAND(), $O$28, $O$29) -> 138.49825 | D13: =_xlfn.LOGNORM.INV(RAND(), $O$25, $O$26) -> 41.793388 | E13: =((B13-$B$5)/0.1)*$D$5 + ((C13-$B$6)/10)*$D$6 + ((D13-$B$7)/10)*$D$7 -> -88.479763 | F13: =IF(OR(B13<0.4, D13>50), 150, 0) -> 0 | G13: =(D13/10)*D11 -> 36.274551 | H13: =E13+F13+G13 -> -52.205212 | J13: =CORREL(B9:B1008,C9:C1008) -> 0.056659375 | M13: Q4 2022 | N13: 1.82 | O13: 65.78 | P13: 34
A14: 6 | B14: =_xlfn.LOGNORM.INV(RAND(), $O$31, $O$32) -> 1.3007729 | C14: =_xlfn.LOGNORM.INV(RAND(), $O$28, $O$29) -> 48.706841 | D14: =_xlfn.LOGNORM.INV(RAND(), $O$25, $O$26) -> 19.610699 | E14: =((B14-$B$5)/0.1)*$D$5 + ((C14-$B$6)/10)*$D$6 + ((D14-$B$7)/10)*$D$7 -> -340.0849 | F14: =IF(OR(B14<0.4, D14>50), 150, 0) -> 0 | G14: =(D14/10)*D12 -> 87.825367 | H14: =E14+F14+G14 -> -252.25953 | J14: =CORREL(D9:D1008,C9:C1008) -> 0.035879679 | M14: Q1 2023 | N14: 1.63 | O14: 65.68 | P14: 65
A15: 7 | B15: =_xlfn.LOGNORM.INV(RAND(), $O$31, $O$32) -> 0.49038156 | C15: =_xlfn.LOGNORM.INV(RAND(), $O$28, $O$29) -> 133.8892 | D15: =_xlfn.LOGNORM.INV(RAND(), $O$25, $O$26) -> 68.082269 | E15: =((B15-$B$5)/0.1)*$D$5 + ((C15-$B$6)/10)*$D$6 + ((D15-$B$7)/10)*$D$7 -> -47.609 | F15: =IF(OR(B15<0.4, D15>50), 150, 0) -> 150 | G15: =(D15/10)*D13 -> 284.53887 | H15: =E15+F15+G15 -> 386.92987 | M15: Q2 2023 | N15: 1.51 | O15: 80.81 | P15: 66
A16: 8 | B16: =_xlfn.LOGNORM.INV(RAND(), $O$31, $O$32) -> 1.7123072 | C16: =_xlfn.LOGNORM.INV(RAND(), $O$28, $O$29) -> 269.13472 | D16: =_xlfn.LOGNORM.INV(RAND(), $O$25, $O$26) -> 104.70528 | E16: =((B16-$B$5)/0.1)*$D$5 + ((C16-$B$6)/10)*$D$6 + ((D16-$B$7)/10)*$D$7 -> 1267.6977 | F16: =IF(OR(B16<0.4, D16>50), 150, 0) -> 150 | G16: =(D16/10)*D14 -> 205.33436 | H16: =E16+F16+G16 -> 1623.0321 | J16: =AVERAGE(E9:E1008) -> 21.383579 | M16: Q3 2023 | N16: 1.4 | O16: 74.46 | P16: 72
A17: 9 | B17: =_xlfn.LOGNORM.INV(RAND(), $O$31, $O$32) -> 0.44269275 | C17: =_xlfn.LOGNORM.INV(RAND(), $O$28, $O$29) -> 90.267029 | D17: =_xlfn.LOGNORM.INV(RAND(), $O$25, $O$26) -> 44.366983 | E17: =((B17-$B$5)/0.1)*$D$5 + ((C17-$B$6)/10)*$D$6 + ((D17-$B$7)/10)*$D$7 -> -417.66168 | F17: =IF(OR(B17<0.4, D17>50), 150, 0) -> 0 | G17: =(D17/10)*D15 -> 302.06049 | H17: =E17+F17+G17 -> -115.60119 | M17: Q4 2023 | N17: 0.84 | O17: 68.71 | P17: 65
A18: 10 | B18: =_xlfn.LOGNORM.INV(RAND(), $O$31, $O$32) -> 1.5254351 | C18: =_xlfn.LOGNORM.INV(RAND(), $O$28, $O$29) -> 84.934945 | D18: =_xlfn.LOGNORM.INV(RAND(), $O$25, $O$26) -> 18.169035 | E18: =((B18-$B$5)/0.1)*$D$5 + ((C18-$B$6)/10)*$D$6 + ((D18-$B$7)/10)*$D$7 -> -151.60017 | F18: =IF(OR(B18<0.4, D18>50), 150, 0) -> 0 | G18: =(D18/10)*D16 -> 190.23939 | H18: =E18+F18+G18 -> 38.639218 | M18: Q1 2024 | N18: 0.58 | O18: 63.55 | P18: 70
A19: 11 | B19: =_xlfn.LOGNORM.INV(RAND(), $O$31, $O$32) -> 0.6651088 | C19: =_xlfn.LOGNORM.INV(RAND(), $O$28, $O$29) -> 89.015006 | D19: =_xlfn.LOGNORM.INV(RAND(), $O$25, $O$26) -> 16.025448 | E19: =((B19-$B$5)/0.1)*$D$5 + ((C19-$B$6)/10)*$D$6 + ((D19-$B$7)/10)*$D$7 -> -592.99906 | F19: =IF(OR(B19<0.4, D19>50), 150, 0) -> 0 | G19: =(D19/10)*D17 -> 71.100076 | H19: =E19+F19+G19 -> -521.89899 | M19: Q2 2024 | N19: 0.51 | O19: 51.29 | P19: 75
A20: 12 | B20: =_xlfn.LOGNORM.INV(RAND(), $O$31, $O$32) -> 1.3020368 | C20: =_xlfn.LOGNORM.INV(RAND(), $O$28, $O$29) -> 76.131808 | D20: =_xlfn.LOGNORM.INV(RAND(), $O$25, $O$26) -> 28.659939 | E20: =((B20-$B$5)/0.1)*$D$5 + ((C20-$B$6)/10)*$D$6 + ((D20-$B$7)/10)*$D$7 -> -180.39813 | F20: =IF(OR(B20<0.4, D20>50), 150, 0) -> 0 | G20: =(D20/10)*D18 -> 52.072344 | H20: =E20+F20+G20 -> -128.32578 | M20: Q3 2024 | N20: 0.6 | O20: 53.65 | P20: 76
A21: 13 | B21: =_xlfn.LOGNORM.INV(RAND(), $O$31, $O$32) -> 1.805974 | C21: =_xlfn.LOGNORM.INV(RAND(), $O$28, $O$29) -> 158.69628 | D21: =_xlfn.LOGNORM.INV(RAND(), $O$25, $O$26) -> 131.61041 | E21: =((B21-$B$5)/0.1)*$D$5 + ((C21-$B$6)/10)*$D$6 + ((D21-$B$7)/10)*$D$7 -> 1307.4864 | F21: =IF(OR(B21<0.4, D21>50), 150, 0) -> 150 | G21: =(D21/10)*D19 -> 210.91158 | H21: =E21+F21+G21 -> 1668.398 | M21: Q4 2024 | N21: 0.84 | O21: 68.71 | P21: 78
A22: 14 | B22: =_xlfn.LOGNORM.INV(RAND(), $O$31, $O$32) -> 0.6104641 | C22: =_xlfn.LOGNORM.INV(RAND(), $O$28, $O$29) -> 173.06267 | D22: =_xlfn.LOGNORM.INV(RAND(), $O$25, $O$26) -> 57.996454 | E22: =((B22-$B$5)/0.1)*$D$5 + ((C22-$B$6)/10)*$D$6 + ((D22-$B$7)/10)*$D$7 -> 9.5078144 | F22: =IF(OR(B22<0.4, D22>50), 150, 0) -> 150 | G22: =(D22/10)*D20 -> 166.21749 | H22: =E22+F22+G22 -> 325.7253 | M22: Q1 2025 | N22: 0.79 | O22: 66.17 | P22: 82
A23: 15 | B23: =_xlfn.LOGNORM.INV(RAND(), $O$31, $O$32) -> 0.65497386 | C23: =_xlfn.LOGNORM.INV(RAND(), $O$28, $O$29) -> 147.12549 | D23: =_xlfn.LOGNORM.INV(RAND(), $O$25, $O$26) -> 28.729568 | E23: =((B23-$B$5)/0.1)*$D$5 + ((C23-$B$6)/10)*$D$6 + ((D23-$B$7)/10)*$D$7 -> -325.74912 | F23: =IF(OR(B23<0.4, D23>50), 150, 0) -> 0 | G23: =(D23/10)*D21 -> 378.11104 | H23: =E23+F23+G23 -> 52.36192 | M23: Q2 2025 | N23: 0.94 | O23: 52.36 | P23: 90
A24: 16 | B24: =_xlfn.LOGNORM.INV(RAND(), $O$31, $O$32) -> 0.55981938 | C24: =_xlfn.LOGNORM.INV(RAND(), $O$28, $O$29) -> 29.894758 | D24: =_xlfn.LOGNORM.INV(RAND(), $O$25, $O$26) -> 50.828455 | E24: =((B24-$B$5)/0.1)*$D$5 + ((C24-$B$6)/10)*$D$6 + ((D24-$B$7)/10)*$D$7 -> -445.41432 | F24: =IF(OR(B24<0.4, D24>50), 150, 0) -> 150 | G24: =(D24/10)*D22 -> 294.78702 | H24: =E24+F24+G24 -> -0.62730109
A25: 17 | B25: =_xlfn.LOGNORM.INV(RAND(), $O$31, $O$32) -> 1.0455131 | C25: =_xlfn.LOGNORM.INV(RAND(), $O$28, $O$29) -> 260.40649 | D25: =_xlfn.LOGNORM.INV(RAND(), $O$25, $O$26) -> 150.68416 | E25: =((B25-$B$5)/0.1)*$D$5 + ((C25-$B$6)/10)*$D$6 + ((D25-$B$7)/10)*$D$7 -> 1372.269 | F25: =IF(OR(B25<0.4, D25>50), 150, 0) -> 150 | G25: =(D25/10)*D23 -> 432.90909 | H25: =E25+F25+G25 -> 1955.1781 | L25: CARBON PRICE | M25: Mean of natural logs : | O25: {=AVERAGE(LN(P2:P23))} -> 3.6330366
A26: 18 | B26: =_xlfn.LOGNORM.INV(RAND(), $O$31, $O$32) -> 0.98382297 | C26: =_xlfn.LOGNORM.INV(RAND(), $O$28, $O$29) -> 126.1742 | D26: =_xlfn.LOGNORM.INV(RAND(), $O$25, $O$26) -> 31.319349 | E26: =((B26-$B$5)/0.1)*$D$5 + ((C26-$B$6)/10)*$D$6 + ((D26-$B$7)/10)*$D$7 -> -187.80498 | F26: =IF(OR(B26<0.4, D26>50), 150, 0) -> 0 | G26: =(D26/10)*D24 -> 159.19141 | H26: =E26+F26+G26 -> -28.613563 | M26: Standard deviation of natural logs : | O26: {=_xlfn.STDEV.S(LN(P2:P23))} -> 0.67533349
A27: 19 | B27: =_xlfn.LOGNORM.INV(RAND(), $O$31, $O$32) -> 0.84691627 | C27: =_xlfn.LOGNORM.INV(RAND(), $O$28, $O$29) -> 144.67512 | D27: =_xlfn.LOGNORM.INV(RAND(), $O$25, $O$26) -> 74.659596 | E27: =((B27-$B$5)/0.1)*$D$5 + ((C27-$B$6)/10)*$D$6 + ((D27-$B$7)/10)*$D$7 -> 223.39645 | F27: =IF(OR(B27<0.4, D27>50), 150, 0) -> 150 | G27: =(D27/10)*D25 -> 1125.0019 | H27: =E27+F27+G27 -> 1498.3983
A28: 20 | B28: =_xlfn.LOGNORM.INV(RAND(), $O$31, $O$32) -> 1.0275686 | C28: =_xlfn.LOGNORM.INV(RAND(), $O$28, $O$29) -> 66.249515 | D28: =_xlfn.LOGNORM.INV(RAND(), $O$25, $O$26) -> 41.832461 | E28: =((B28-$B$5)/0.1)*$D$5 + ((C28-$B$6)/10)*$D$6 + ((D28-$B$7)/10)*$D$7 -> -210.61276 | F28: =IF(OR(B28<0.4, D28>50), 150, 0) -> 0 | G28: =(D28/10)*D26 -> 131.01654 | H28: =E28+F28+G28 -> -79.596213 | L28: LCFS Price | M28: Mean of natural logs : | O28: {=AVERAGE(LN(O2:O23))} -> 4.627254
A29: 21 | B29: =_xlfn.LOGNORM.INV(RAND(), $O$31, $O$32) -> 1.5637059 | C29: =_xlfn.LOGNORM.INV(RAND(), $O$28, $O$29) -> 88.79598 | D29: =_xlfn.LOGNORM.INV(RAND(), $O$25, $O$26) -> 36.199965 | E29: =((B29-$B$5)/0.1)*$D$5 + ((C29-$B$6)/10)*$D$6 + ((D29-$B$7)/10)*$D$7 -> 57.497086 | F29: =IF(OR(B29<0.4, D29>50), 150, 0) -> 0 | G29: =(D29/10)*D27 -> 270.26748 | H29: =E29+F29+G29 -> 327.76456 | M29: Standard deviation of natural logs : | O29: {=_xlfn.STDEV.S(LN(O2:O23))} -> 0.53034028
A30: 22 | B30: =_xlfn.LOGNORM.INV(RAND(), $O$31, $O$32) -> 0.93345634 | C30: =_xlfn.LOGNORM.INV(RAND(), $O$28, $O$29) -> 104.80325 | D30: =_xlfn.LOGNORM.INV(RAND(), $O$25, $O$26) -> 24.521803 | E30: =((B30-$B$5)/0.1)*$D$5 + ((C30-$B$6)/10)*$D$6 + ((D30-$B$7)/10)*$D$7 -> -334.39114 | F30: =IF(OR(B30<0.4, D30>50), 150, 0) -> 0 | G30: =(D30/10)*D28 -> 102.58073 | H30: =E30+F30+G30 -> -231.8104
A31: 23 | B31: =_xlfn.LOGNORM.INV(RAND(), $O$31, $O$32) -> 0.72990423 | C31: =_xlfn.LOGNORM.INV(RAND(), $O$28, $O$29) -> 89.482523 | D31: =_xlfn.LOGNORM.INV(RAND(), $O$25, $O$26) -> 69.992076 | E31: =((B31-$B$5)/0.1)*$D$5 + ((C31-$B$6)/10)*$D$6 + ((D31-$B$7)/10)*$D$7 -> -19.766269 | F31: =IF(OR(B31<0.4, D31>50), 150, 0) -> 150 | G31: =(D31/10)*D29 -> 253.37107 | H31: =E31+F31+G31 -> 383.6048 | L31: RIN Price | M31: Mean of natural logs : | O31: {=AVERAGE(LN(N2:N23))} -> 0.010493868
A32: 24 | B32: =_xlfn.LOGNORM.INV(RAND(), $O$31, $O$32) -> 1.4271293 | C32: =_xlfn.LOGNORM.INV(RAND(), $O$28, $O$29) -> 116.41225 | D32: =_xlfn.LOGNORM.INV(RAND(), $O$25, $O$26) -> 33.007079 | E32: =((B32-$B$5)/0.1)*$D$5 + ((C32-$B$6)/10)*$D$6 + ((D32-$B$7)/10)*$D$7 -> 26.320624 | F32: =IF(OR(B32<0.4, D32>50), 150, 0) -> 0 | G32: =(D32/10)*D30 -> 80.939307 | H32: =E32+F32+G32 -> 107.25993 | M32: Standard deviation of natural logs : | O32: {=_xlfn.STDEV.S(LN(N2:N23))} -> 0.45604731
A33: 25 | B33: =_xlfn.LOGNORM.INV(RAND(), $O$31, $O$32) -> 1.2327417 | C33: =_xlfn.LOGNORM.INV(RAND(), $O$28, $O$29) -> 127.6799 | D33: =_xlfn.LOGNORM.INV(RAND(), $O$25, $O$26) -> 84.676063 | E33: =((B33-$B$5)/0.1)*$D$5 + ((C33-$B$6)/10)*$D$6 + ((D33-$B$7)/10)*$D$7 -> 473.98576 | F33: =IF(OR(B33<0.4, D33>50), 150, 0) -> 150 | G33: =(D33/10)*D31 -> 592.66535 | H33: =E33+F33+G33 -> 1216.6511
A34: 26 | B34: =_xlfn.LOGNORM.INV(RAND(), $O$31, $O$32) -> 1.2025477 | C34: =_xlfn.LOGNORM.INV(RAND(), $O$28, $O$29) -> 191.92547 | D34: =_xlfn.LOGNORM.INV(RAND(), $O$25, $O$26) -> 8.4562308 | E34: =((B34-$B$5)/0.1)*$D$5 + ((C34-$B$6)/10)*$D$6 + ((D34-$B$7)/10)*$D$7 -> -142.69562 | F34: =IF(OR(B34<0.4, D34>50), 150, 0) -> 0 | G34: =(D34/10)*D32 -> 27.911547 | H34: =E34+F34+G34 -> -114.78407
A35: 27 | B35: =_xlfn.LOGNORM.INV(RAND(), $O$31, $O$32) -> 1.4661783 | C35: =_xlfn.LOGNORM.INV(RAND(), $O$28, $O$29) -> 113.8645 | D35: =_xlfn.LOGNORM.INV(RAND(), $O$25, $O$26) -> 46.433699 | E35: =((B35-$B$5)/0.1)*$D$5 + ((C35-$B$6)/10)*$D$6 + ((D35-$B$7)/10)*$D$7 -> 173.74195 | F35: =IF(OR(B35<0.4, D35>50), 150, 0) -> 0 | G35: =(D35/10)*D33 -> 393.18229 | H35: =E35+F35+G35 -> 566.92424
A36: 28 | B36: =_xlfn.LOGNORM.INV(RAND(), $O$31, $O$32) -> 1.594518 | C36: =_xlfn.LOGNORM.INV(RAND(), $O$28, $O$29) -> 145.16911 | D36: =_xlfn.LOGNORM.INV(RAND(), $O$25, $O$26) -> 22.518109 | E36: =((B36-$B$5)/0.1)*$D$5 + ((C36-$B$6)/10)*$D$6 + ((D36-$B$7)/10)*$D$7 -> 77.0174 | F36: =IF(OR(B36<0.4, D36>50), 150, 0) -> 0 | G36: =(D36/10)*D34 -> 19.041833 | H36: =E36+F36+G36 -> 96.059232
A37: 29 | B37: =_xlfn.LOGNORM.INV(RAND(), $O$31, $O$32) -> 0.89158757 | C37: =_xlfn.LOGNORM.INV(RAND(), $O$28, $O$29) -> 108.88451 | D37: =_xlfn.LOGNORM.INV(RAND(), $O$25, $O$26) -> 70.425934 | E37: =((B37-$B$5)/0.1)*$D$5 + ((C37-$B$6)/10)*$D$6 + ((D37-$B$7)/10)*$D$7 -> 113.91895 | F37: =IF(OR(B37<0.4, D37>50), 150, 0) -> 150 | G37: =(D37/10)*D35 -> 327.01366 | H37: =E37+F37+G37 -> 590.93262
A38: 30 | B38: =_xlfn.LOGNORM.INV(RAND(), $O$31, $O$32) -> 1.5050401 | C38: =_xlfn.LOGNORM.INV(RAND(), $O$28, $O$29) -> 58.294505 | D38: =_xlfn.LOGNORM.INV(RAND(), $O$25, $O$26) -> 36.615339 | E38: =((B38-$B$5)/0.1)*$D$5 + ((C38-$B$6)/10)*$D$6 + ((D38-$B$7)/10)*$D$7 -> -43.935762 | F38: =IF(OR(B38<0.4, D38>50), 150, 0) -> 0 | G38: =(D38/10)*D36 -> 82.450819 | H38: =E38+F38+G38 -> 38.515058
A39: 31 | B39: =_xlfn.LOGNORM.INV(RAND(), $O$31, $O$32) -> 1.2492307 | C39: =_xlfn.LOGNORM.INV(RAND(), $O$28, $O$29) -> 123.39102 | D39: =_xlfn.LOGNORM.INV(RAND(), $O$25, $O$26) -> 14.547584 | E39: =((B39-$B$5)/0.1)*$D$5 + ((C39-$B$6)/10)*$D$6 + ((D39-$B$7)/10)*$D$7 -> -229.77672 | F39: =IF(OR(B39<0.4, D39>50), 150, 0) -> 0 | G39: =(D39/10)*D37 -> 102.45272 | H39: =E39+F39+G39 -> -127.32401
A40: 32 | B40: =_xlfn.LOGNORM.INV(RAND(), $O$31, $O$32) -> 1.2384542 | C40: =_xlfn.LOGNORM.INV(RAND(), $O$28, $O$29) -> 26.366217 | D40: =_xlfn.LOGNORM.INV(RAND(), $O$25, $O$26) -> 83.671246 | E40: =((B40-$B$5)/0.1)*$D$5 + ((C40-$B$6)/10)*$D$6 + ((D40-$B$7)/10)*$D$7 -> 213.50968 | F40: =IF(OR(B40<0.4, D40>50), 150, 0) -> 150 | G40: =(D40/10)*D38 -> 306.3651 | H40: =E40+F40+G40 -> 669.87478
...

Sheet Sneha
A1: Credit price mean ($/credit) | B1: 38
A2: Credit price stdev ($) | B2: 7
A3: Compliance exposure (credits/yr) | B3: 9500000
A4: Internal offset % | B4: 0.45
A5: Pass-through % | B5: 0.3 | N5: compliance cost formula
A6: Accrued fraction % | B6: 0.3 | N6: =(C12*B12*(1-B5)*(1-B4))/B8 -> 135.26226
A7: Sim paths (rows) | B7: 1000
A8: $ scale (1 for $, 1,000,000 for $M) | B8: 1000000
A11: Path | B11: Carbon Credit Price ($) | C11: Exposure | D11: Offset % | E11: Gross Cost | F11: Offset $ | G11: Net After Offset | H11: Pass-Through $ | I11: Compliance Cost | J11: ΔNWC ($M) | K11: Curr Liab Δ ($M) | L11: Equity Δ ($M)
A12: =ROW()-11 -> 1 | B12: =_xlfn.NORM.INV(RAND(),$B$1,$B$2) -> 36.982162 | C12: =$B$3 -> 9500000 | D12: =$B$4 -> 0.45 | E12: =(B12*C12)/$B$8 -> 351.33054 | F12: =E12*D12 -> 158.09874 | G12: =E12-F12 -> 193.23179 | H12: =G12*$B$5 -> 57.969538 | I12: =G12-H12 -> 135.26226 | J12: =I12*(1-$B$6) -> 94.683579 | K12: =-I12*$B$6 -> -40.578677 | L12: =-I12 -> -135.26226
A13: =ROW()-11 -> 2 | B13: =_xlfn.NORM.INV(RAND(),$B$1,$B$2) -> 23.07436 | C13: =$B$3 -> 9500000 | D13: =$B$4 -> 0.45 | E13: =(B13*C13)/$B$8 -> 219.20642 | F13: =E13*D13 -> 98.642891 | G13: =E13-F13 -> 120.56353 | H13: =G13*$B$5 -> 36.16906 | I13: =G13-H13 -> 84.394473 | J13: =I13*(1-$B$6) -> 59.076131 | K13: =-I13*$B$6 -> -25.318342 | L13: =-I13 -> -84.394473
A14: =ROW()-11 -> 3 | B14: =_xlfn.NORM.INV(RAND(),$B$1,$B$2) -> 41.802983 | C14: =$B$3 -> 9500000 | D14: =$B$4 -> 0.45 | E14: =(B14*C14)/$B$8 -> 397.12834 | F14: =E14*D14 -> 178.70775 | G14: =E14-F14 -> 218.42059 | H14: =G14*$B$5 -> 65.526176 | I14: =G14-H14 -> 152.89441 | J14: =I14*(1-$B$6) -> 107.02609 | K14: =-I14*$B$6 -> -45.868323 | L14: =-I14 -> -152.89441 | N14: Average Compliance Cost | O14: =AVERAGE(I20:INDEX(I:I,19+$B$7)) -> 139.88173
A15: =ROW()-11 -> 4 | B15: =_xlfn.NORM.INV(RAND(),$B$1,$B$2) -> 41.229883 | C15: =$B$3 -> 9500000 | D15: =$B$4 -> 0.45 | E15: =(B15*C15)/$B$8 -> 391.68389 | F15: =E15*D15 -> 176.25775 | G15: =E15-F15 -> 215.42614 | H15: =G15*$B$5 -> 64.627842 | I15: =G15-H15 -> 150.7983 | J15: =I15*(1-$B$6) -> 105.55881 | K15: =-I15*$B$6 -> -45.239489 | L15: =-I15 -> -150.7983 | N15: P5 (worst case) | O15: =_xlfn.PERCENTILE.INC(I20:INDEX(I:I,19+$B$7),0.05) -> 98.93809
A16: =ROW()-11 -> 5 | B16: =_xlfn.NORM.INV(RAND(),$B$1,$B$2) -> 34.515772 | C16: =$B$3 -> 9500000 | D16: =$B$4 -> 0.45 | E16: =(B16*C16)/$B$8 -> 327.89984 | F16: =E16*D16 -> 147.55493 | G16: =E16-F16 -> 180.34491 | H16: =G16*$B$5 -> 54.103473 | I16: =G16-H16 -> 126.24144 | J16: =I16*(1-$B$6) -> 88.369006 | K16: =-I16*$B$6 -> -37.872431 | L16: =-I16 -> -126.24144 | N16: P95 (best case) | O16: =_xlfn.PERCENTILE.INC(I20:INDEX(I:I,19+$B$7),0.95) -> 181.84693
A17: =ROW()-11 -> 6 | B17: =_xlfn.NORM.INV(RAND(),$B$1,$B$2) -> 46.138169 | C17: =$B$3 -> 9500000 | D17: =$B$4 -> 0.45 | E17: =(B17*C17)/$B$8 -> 438.3126 | F17: =E17*D17 -> 197.24067 | G17: =E17-F17 -> 241.07193 | H17: =G17*$B$5 -> 72.321579 | I17: =G17-H17 -> 168.75035 | J17: =I17*(1-$B$6) -> 118.12525 | K17: =-I17*$B$6 -> -50.625106 | L17: =-I17 -> -168.75035 | N17: Std Dev | O17: =_xlfn.STDEV.P(I20:INDEX(I:I,19+$B$7)) -> 25.40655
A18: =ROW()-11 -> 7 | B18: =_xlfn.NORM.INV(RAND(),$B$1,$B$2) -> 40.077711 | C18: =$B$3 -> 9500000 | D18: =$B$4 -> 0.45 | E18: =(B18*C18)/$B$8 -> 380.73826 | F18: =E18*D18 -> 171.33222 | G18: =E18-F18 -> 209.40604 | H18: =G18*$B$5 -> 62.821813 | I18: =G18-H18 -> 146.58423 | J18: =I18*(1-$B$6) -> 102.60896 | K18: =-I18*$B$6 -> -43.975269 | L18: =-I18 -> -146.58423
A19: =ROW()-11 -> 8 | B19: =_xlfn.NORM.INV(RAND(),$B$1,$B$2) -> 36.41847 | C19: =$B$3 -> 9500000 | D19: =$B$4 -> 0.45 | E19: =(B19*C19)/$B$8 -> 345.97547 | F19: =E19*D19 -> 155.68896 | G19: =E19-F19 -> 190.28651 | H19: =G19*$B$5 -> 57.085952 | I19: =G19-H19 -> 133.20055 | J19: =I19*(1-$B$6) -> 93.240388 | K19: =-I19*$B$6 -> -39.960166 | L19: =-I19 -> -133.20055 | N19: Balancesheet Summary
A20: =ROW()-11 -> 9 | B20: =_xlfn.NORM.INV(RAND(),$B$1,$B$2) -> 44.001329 | C20: =$B$3 -> 9500000 | D20: =$B$4 -> 0.45 | E20: =(B20*C20)/$B$8 -> 418.01262 | F20: =E20*D20 -> 188.10568 | G20: =E20-F20 -> 229.90694 | H20: =G20*$B$5 -> 68.972082 | I20: =G20-H20 -> 160.93486 | J20: =I20*(1-$B$6) -> 112.6544 | K20: =-I20*$B$6 -> -48.280458 | L20: =-I20 -> -160.93486 | N20: Average Compliance Cost ($M) | O20: =AVERAGE(I20:INDEX(I:I,19+$B$7)) -> 139.88173
